<?xml version="1.0"?>
<!-- =================================================================================== -->
<!-- |    This document was autogenerated by xacro from galbot_one_charlie.xacro       | -->
<!-- |    EDITING THIS FILE BY HAND IS NOT RECOMMENDED                                 | -->
<!-- =================================================================================== -->
<!-- 
#####################################################################################
#
# Copyright (c) 2023-2025 Galbot, Inc. All rights Reserved.
#
# This software contains confidential and proprietary information of Galbot, Inc.
# ("Confidential Information"). You shall not disclose such Confidential Information
# and shall use it only in accordance with the terms of the license agreement you
# entered into with Galbot, Inc.
#
# UNAUTHORIZED COPYING, USE, OR DISTRIBUTION OF THIS SOFTWARE, OR ANY PORTION OR
# DERIVATIVE THEREOF, IS STRICTLY PROHIBITED. IF YOU HAVE RECEIVED THIS SOFTWARE IN
# ERROR, PLEASE NOTIFY GALBOT, INC. IMMEDIATELY AND DELETE IT FROM YOUR SYSTEM.
#
#####################################################################################
#
# Description: URDF file for Galbot One Charlie.
# Author: Herman Ye@Galbot, Yuhao Zeng@Galbot
#
#####################################################################################
-->
<robot name="galbot_one_charlie">
  <!-- ROBOT -->
  <!-- Robot Base Link -->
  <link name="base_link">
  </link>
  <joint name="omni_chassis_joint" type="fixed">
    <origin rpy="0 0 0" xyz="0 0 0" />
    <parent link="base_link" />
    <child link="omni_chassis_base_link" />
  </joint>
  <link name="omni_chassis_base_link">
    <inertial>
      <origin rpy="0 0 0" xyz="0.00310 0.00022 0.09001" />
      <mass value="25.85" />
      <inertia ixx="1.12288" ixy="0.0" ixz="0.0" iyy="1.15522" iyz="0.0" izz="1.58321" />
    </inertial>
    <visual>
      <origin rpy="0 0 0" xyz="0 0 0" />
      <geometry>
        <mesh filename="meshes/chassis/omni_chassis_base_link.obj" />
      </geometry>
    </visual>
    <collision>
      <origin rpy="0 0 0" xyz="0 0 0" />
      <geometry>
        <mesh filename="meshes/chassis/omni_chassis_base_link.stl" />
      </geometry>
    </collision>
  </link>
  <link name="omni_chassis_leg_mount_link">
    <inertial>
      <origin rpy="0 0 0" xyz="0 0 0" />
      <mass value="0" />
      <inertia ixx="0" ixy="0" ixz="0" iyy="0" iyz="0" izz="0" />
    </inertial>
  </link>
  <joint name="omni_chassis_leg_mount_joint" type="fixed">
    <origin rpy="0 0 0" xyz="0.134 0 0.13" />
    <parent link="omni_chassis_base_link" />
    <child link="omni_chassis_leg_mount_link" />
    <axis xyz="0 0 0" />
  </joint>
  <joint name="leg_joint" type="fixed">
    <origin rpy="0 0 0" xyz="0 0 0" />
    <parent link="omni_chassis_leg_mount_link" />
    <child link="leg_base_link" />
  </joint>
  <link name="leg_base_link">
    <inertial>
      <origin rpy="0 0 0" xyz="0.00138 -0.01502 -0.05360" />
      <mass value="1.98" />
      <inertia ixx="0.01545" ixy="0.0" ixz="0.0" iyy="0.01172" iyz="0.0" izz="0.00904" />
    </inertial>
  </link>
  <link name="leg_link1">
    <inertial>
      <origin rpy="0 0 0" xyz="0.23126 0.00187 -0.01166" />
      <mass value="13.38" />
      <inertia ixx="0.05540" ixy="0.00267" ixz="-0.03511" iyy="1.17040" iyz="-0.00012" izz="1.15967" />
    </inertial>
    <visual>
      <origin rpy="0 0 0" xyz="0 0 0" />
      <geometry>
        <mesh filename="meshes/leg/leg_link1.obj" />
      </geometry>
    </visual>
    <collision>
      <origin rpy="0 0 0" xyz="0 0 0" />
      <geometry>
        <mesh filename="meshes/leg/leg_link1.stl" />
      </geometry>
    </collision>
  </link>
  <joint name="leg_joint1" type="revolute">
    <origin rpy="-1.5707963267948966 -2.756573021 0" xyz="0 0 0" />
    <parent link="leg_base_link" />
    <child link="leg_link1" />
    <axis xyz="0 0 1" />
    <limit effort="169" lower="0" upper="0.994837674" velocity="1" />
  </joint>
  <link name="leg_link2">
    <inertial>
      <origin rpy="0 0 0" xyz="0.18340 0.00001 0.01143" />
      <mass value="4.72" />
      <inertia ixx="0.04727" ixy="0.00001" ixz="0.01147" iyy="0.29026" iyz="0.00001" izz="0.25782" />
    </inertial>
    <visual>
      <origin rpy="0 0 0" xyz="0 0 0" />
      <geometry>
        <mesh filename="meshes/leg/leg_link2.obj" />
      </geometry>
    </visual>
    <collision>
      <origin rpy="0 0 0" xyz="0 0 0" />
      <geometry>
        <mesh filename="meshes/leg/leg_link2.stl" />
      </geometry>
    </collision>
  </link>
  <joint name="leg_joint2" type="revolute">
    <origin rpy="-3.141592653589793 0 2.756573021" xyz="0.45 0 0" />
    <parent link="leg_link1" />
    <child link="leg_link2" />
    <axis xyz="0 0 1" />
    <limit effort="169" lower="0" upper="3.05" velocity="1" />
  </joint>
  <link name="leg_link3">
    <inertial>
      <origin rpy="0 0 0" xyz="0.00004 0.03287 -0.00556" />
      <mass value="6.04" />
      <inertia ixx="0.02981" ixy="0.00001" ixz="-0.00000" iyy="0.02294" iyz="-0.00079" izz="0.03182" />
    </inertial>
    <visual>
      <origin rpy="0 0 0" xyz="0 0 0" />
      <geometry>
        <mesh filename="meshes/leg/leg_link3.obj" />
      </geometry>
    </visual>
    <collision>
      <origin rpy="0 0 0" xyz="0 0 0" />
      <geometry>
        <mesh filename="meshes/leg/leg_link3.stl" />
      </geometry>
    </collision>
  </link>
  <joint name="leg_joint3" type="revolute">
    <origin rpy="-3.141592653589793 0 -3.141592653589793" xyz="0.39 0 0" />
    <parent link="leg_link2" />
    <child link="leg_link3" />
    <axis xyz="0 0 1" />
    <limit effort="84" lower="0" upper="2.35619449" velocity="1" />
  </joint>
  <link name="leg_link4">
    <inertial>
      <origin rpy="0 0 0" xyz="0.00006 -0.00003 0.14494" />
      <mass value="0.55" />
      <inertia ixx="0.01267" ixy="0.00000" ixz="0.00001" iyy="0.01270" iyz="-0.00000" izz="0.00125" />
    </inertial>
    <visual>
      <origin rpy="0 0 0" xyz="0 0 0" />
      <geometry>
        <mesh filename="meshes/leg/leg_link4.obj" />
      </geometry>
    </visual>
    <collision>
      <origin rpy="0 0 0" xyz="0 0 0" />
      <geometry>
        <mesh filename="meshes/leg/leg_link4.stl" />
      </geometry>
    </collision>
  </link>
  <joint name="leg_joint4" type="revolute">
    <origin rpy="1.5707963267948966 0 -3.141592653589793" xyz="0 0 0" />
    <parent link="leg_link3" />
    <child link="leg_link4" />
    <axis xyz="0 0 1" />
    <limit effort="30" lower="-1.570796327" upper="1.570796327" velocity="1" />
  </joint>
  <link name="leg_end_effector_mount_link">
    <inertial>
      <origin rpy="0 0 0" xyz="0 0 0" />
      <mass value="0" />
      <inertia ixx="0" ixy="0" ixz="0" iyy="0" iyz="0" izz="0" />
    </inertial>
  </link>
  <joint name="leg_end_effector_mount_joint" type="fixed">
    <origin rpy="0 0 0" xyz="0 0 0" />
    <parent link="leg_link4" />
    <child link="leg_end_effector_mount_link" />
    <axis xyz="0 0 0" />
  </joint>
  <joint name="torso_joint" type="fixed">
    <origin rpy="0 0 0" xyz="0 0 0" />
    <parent link="leg_end_effector_mount_link" />
    <child link="torso_base_link" />
  </joint>
  <link name="torso_base_link">
    <inertial>
      <origin rpy="0 0 0" xyz="0.00004 0.00011 0.32719" />
      <mass value="6.68" />
      <inertia ixx="0.87119" ixy="0.00009" ixz="-0.00496" iyy="0.85457" iyz="0.00295" izz="0.06560" />
    </inertial>
    <visual>
      <origin rpy="0 0 0" xyz="0 0 0" />
      <geometry>
        <mesh filename="meshes/torso/torso_base_link.obj" />
      </geometry>
    </visual>
    <collision>
      <origin rpy="0 0 0" xyz="0 0 0" />
      <geometry>
        <mesh filename="meshes/torso/torso_base_link.stl" />
      </geometry>
    </collision>
  </link>
  <!-- Head Mount -->
  <link name="torso_head_mount_link">
    <inertial>
      <origin rpy="0 0 0" xyz="0 0 0" />
      <mass value="0" />
      <inertia ixx="0" ixy="0" ixz="0" iyy="0" iyz="0" izz="0" />
    </inertial>
  </link>
  <joint name="torso_head_mount_joint" type="fixed">
    <origin rpy="0 0 0" xyz="-0.0081669 5E-05 0.58394" />
    <parent link="torso_base_link" />
    <child link="torso_head_mount_link" />
    <axis xyz="0 0 0" />
  </joint>
  <!-- Right Arm Mount -->
  <link name="torso_right_arm_mount_link">
    <inertial>
      <origin rpy="0 0 0" xyz="0 0 0" />
      <mass value="0" />
      <inertia ixx="0" ixy="0" ixz="0" iyy="0" iyz="0" izz="0" />
    </inertial>
  </link>
  <joint name="torso_right_arm_mount_joint" type="fixed">
    <origin rpy="-1.5707963267948966 0 3.141592653589793" xyz="0 -0.206 0.39599" />
    <parent link="torso_base_link" />
    <child link="torso_right_arm_mount_link" />
    <axis xyz="0 0 0" />
  </joint>
  <!-- Left Arm Mount -->
  <link name="torso_left_arm_mount_link">
    <inertial>
      <origin rpy="0 0 0" xyz="0 0 0" />
      <mass value="0" />
      <inertia ixx="0" ixy="0" ixz="0" iyy="0" iyz="0" izz="0" />
    </inertial>
  </link>
  <joint name="torso_left_arm_mount_joint" type="fixed">
    <origin rpy="1.5707963267948966 0 3.141592653589793" xyz="0 0.206 0.39599" />
    <parent link="torso_base_link" />
    <child link="torso_left_arm_mount_link" />
    <axis xyz="0 0 0" />
  </joint>
  <joint name="head_joint" type="fixed">
    <origin rpy="0 0 0" xyz="0 0 0" />
    <parent link="torso_head_mount_link" />
    <child link="head_base_link" />
  </joint>
  <link name="head_base_link">
    <inertial>
      <origin rpy="0 0 0" xyz="0 0 0" />
      <mass value="0" />
      <inertia ixx="0" ixy="0" ixz="0" iyy="0" iyz="0" izz="0" />
    </inertial>
  </link>
  <link name="head_link1">
    <inertial>
      <origin rpy="0 0 0" xyz="0.00000 0.00004 -0.04238" />
      <mass value="0.41" />
      <inertia ixx="0.00110" ixy="-0.00000" ixz="0.00000" iyy="0.00113" iyz="0.00008" izz="0.00014" />
    </inertial>
  </link>
  <joint name="head_joint1" type="revolute">
    <origin rpy="0 0 0" xyz="0 0 0" />
    <parent link="head_base_link" />
    <child link="head_link1" />
    <axis xyz="0 0 1" />
    <limit effort="4" lower="-1.570796327" upper="1.570796327" velocity="1.5" />
  </joint>
  <link name="head_link2">
    <inertial>
      <origin rpy="0 0 0" xyz="0.03200 -0.03753 0.00162" />
      <mass value="0.75" />
      <inertia ixx="0.00380" ixy="-0.00070" ixz="0.00000" iyy="0.00367" iyz="-0.00000" izz="0.00538" />
    </inertial>
    <visual>
      <origin rpy="0 0 0" xyz="0 0 0" />
      <geometry>
        <mesh filename="meshes/head/head_link2.obj" />
      </geometry>
    </visual>
    <collision>
      <origin rpy="0 0 0" xyz="0 0 0" />
      <geometry>
        <mesh filename="meshes/head/head_link2.stl" />
      </geometry>
    </collision>
  </link>
  <joint name="head_joint2" type="revolute">
    <origin rpy="-1.5707963267948966 0 0" xyz="0 0 0" />
    <parent link="head_link1" />
    <child link="head_link2" />
    <axis xyz="0 0 1" />
    <limit effort="4" lower="-0.366519143" upper="0.366519143" velocity="1.5" />
  </joint>
  <link name="head_end_effector_mount_link">
    <inertial>
      <origin rpy="0 0 0" xyz="0 0 0" />
      <mass value="0" />
      <inertia ixx="0" ixy="0" ixz="0" iyy="0" iyz="0" izz="0" />
    </inertial>
  </link>
  <joint name="head_end_effector_mount_joint" type="fixed">
    <origin rpy="0 0 0" xyz="0 0 0" />
    <parent link="head_link2" />
    <child link="head_end_effector_mount_link" />
    <axis xyz="0 0 0" />
  </joint>
  <joint name="right_arm_joint" type="fixed">
    <origin rpy="0 0 0" xyz="0 0 0" />
    <parent link="torso_right_arm_mount_link" />
    <child link="right_arm_base_link" />
  </joint>
  <link name="right_arm_base_link">
    <inertial>
      <origin rpy="0 0 0" xyz="-0.00037 -0.00006 -0.11407" />
      <mass value="0.9" />
      <inertia ixx="0.01248" ixy="0.00000" ixz="0.00003" iyy="0.01247" iyz="0.00003" izz="0.00056" />
    </inertial>
  </link>
  <link name="right_arm_link1">
    <inertial>
      <origin rpy="0 0 0" xyz="0.00000 -0.00650 -0.01459" />
      <mass value="1.48" />
      <inertia ixx="0.00378" ixy="0.00000" ixz="0.00000" iyy="0.00460" iyz="0.00008" izz="0.00217" />
    </inertial>
    <visual>
      <origin rpy="0 0 0" xyz="0 0 0" />
      <geometry>
        <mesh filename="meshes/arm/right_arm_link1.obj" />
      </geometry>
    </visual>
    <collision>
      <origin rpy="0 0 0" xyz="0 0 0" />
      <geometry>
        <mesh filename="meshes/arm/right_arm_link1.stl" />
      </geometry>
    </collision>
  </link>
  <joint name="right_arm_joint1" type="revolute">
    <origin rpy="0 0 0" xyz="0 0 0" />
    <parent link="right_arm_base_link" />
    <child link="right_arm_link1" />
    <axis xyz="0 0 1" />
    <limit acceleration="2" effort="60" jerk="12" lower="-3" upper="3" velocity="1.5" />
    <dynamics damping="0" friction="0" />
  </joint>
  <link name="right_arm_link2">
    <inertial>
      <origin rpy="0 0 0" xyz="-0.00080 -0.09873 0.00815" />
      <mass value="1.33" />
      <inertia ixx="0.01827" ixy="0.00003" ixz="0.00001" iyy="0.00232" iyz="0.00080" izz="0.01769" />
    </inertial>
    <visual>
      <origin rpy="0 0 0" xyz="0 0 0" />
      <geometry>
        <mesh filename="meshes/arm/right_arm_link2.obj" />
      </geometry>
    </visual>
    <collision>
      <origin rpy="0 0 0" xyz="0 0 0" />
      <geometry>
        <mesh filename="meshes/arm/right_arm_link2.stl" />
      </geometry>
    </collision>
  </link>
  <joint name="right_arm_joint2" type="revolute">
    <origin rpy="-1.5707963267948966 0 3.141592653589793" xyz="0 0 0" />
    <parent link="right_arm_link1" />
    <child link="right_arm_link2" />
    <axis xyz="0 0 1" />
    <limit acceleration="2" effort="60" jerk="12" lower="-1.5707963267948966" upper="1.7"
      velocity="1.5" />
    <dynamics damping="0" friction="0" />
  </joint>
  <link name="right_arm_link3">
    <inertial>
      <origin rpy="0 0 0" xyz="-0.00019 -0.00330 -0.04824" />
      <mass value="1.25" />
      <inertia ixx="0.00955" ixy="0.00000" ixz="0.00001" iyy="0.00983" iyz="0.00007" izz="0.00151" />
    </inertial>
    <visual>
      <origin rpy="0 0 0" xyz="0 0 0" />
      <geometry>
        <mesh filename="meshes/arm/right_arm_link3.obj" />
      </geometry>
    </visual>
    <collision>
      <origin rpy="0 0 0" xyz="0 0 0" />
      <geometry>
        <mesh filename="meshes/arm/right_arm_link3.stl" />
      </geometry>
    </collision>
  </link>
  <joint name="right_arm_joint3" type="revolute">
    <origin rpy="1.5707963267948966 -1.5707963267948966 0" xyz="0 -0.35 0" />
    <parent link="right_arm_link2" />
    <child link="right_arm_link3" />
    <axis xyz="0 0 1" />
    <limit acceleration="2" effort="30" jerk="12" lower="-2.9" upper="2.9" velocity="1.5" />
    <dynamics damping="0" friction="0" />
  </joint>
  <link name="right_arm_link4">
    <inertial>
      <origin rpy="0 0 0" xyz="0.00000 -0.06457 0.00899" />
      <mass value="0.8" />
      <inertia ixx="0.00529" ixy="0.00000" ixz="0.00000" iyy="0.00120" iyz="0.00030" izz="0.00488" />
    </inertial>
    <visual>
      <origin rpy="0 0 0" xyz="0 0 0" />
      <geometry>
        <mesh filename="meshes/arm/right_arm_link4.obj" />
      </geometry>
    </visual>
    <collision>
      <origin rpy="0 0 0" xyz="0 0 0" />
      <geometry>
        <mesh filename="meshes/arm/right_arm_link4.stl" />
      </geometry>
    </collision>
  </link>
  <joint name="right_arm_joint4" type="revolute">
    <origin rpy="-1.5707963267948966 0 3.141592653589793" xyz="0 0 0" />
    <parent link="right_arm_link3" />
    <child link="right_arm_link4" />
    <axis xyz="0 0 1" />
    <limit acceleration="2" effort="30" jerk="12" lower="-2.1" upper="2.1" velocity="1.5" />
    <dynamics damping="0" friction="0" />
  </joint>
  <link name="right_arm_link5">
    <inertial>
      <origin rpy="0 0 0" xyz="0.00201 -0.00042 -0.14589" />
      <mass value="1.22" />
      <inertia ixx="0.03428" ixy="0.00001" ixz="0.00032" iyy="0.03366" iyz="0.00005" izz="0.00222" />
    </inertial>
    <visual>
      <origin rpy="0 0 0" xyz="0 0 0" />
      <geometry>
        <mesh filename="meshes/arm/right_arm_link5.obj" />
      </geometry>
    </visual>
    <collision>
      <origin rpy="0 0 0" xyz="0 0 0" />
      <geometry>
        <mesh filename="meshes/arm/right_arm_link5.stl" />
      </geometry>
    </collision>
  </link>
  <joint name="right_arm_joint5" type="revolute">
    <origin rpy="1.5707963267948966 0 0" xyz="0 -0.36 0" />
    <parent link="right_arm_link4" />
    <child link="right_arm_link5" />
    <axis xyz="0 0 1" />
    <limit acceleration="2" effort="10" jerk="12" lower="-2.9" upper="2.9" velocity="1.5" />
    <dynamics damping="0" friction="0" />
  </joint>
  <link name="right_arm_link6">
    <inertial>
      <origin rpy="0 0 0" xyz="0.00000 0.01031 0.00000" />
      <mass value="0.43" />
      <inertia ixx="0.00051" ixy="0.00000" ixz="0.00000" iyy="0.00070" iyz="0.00000" izz="0.00091" />
    </inertial>
    <visual>
      <origin rpy="0 0 0" xyz="0 0 0" />
      <geometry>
        <mesh filename="meshes/arm/right_arm_link6.obj" />
      </geometry>
    </visual>
    <collision>
      <origin rpy="0 0 0" xyz="0 0 0" />
      <geometry>
        <mesh filename="meshes/arm/right_arm_link6.stl" />
      </geometry>
    </collision>
  </link>
  <joint name="right_arm_joint6" type="revolute">
    <origin rpy="-1.5707963267948966 1.5707963267948966 3.141592653589793" xyz="0 0 0" />
    <parent link="right_arm_link5" />
    <child link="right_arm_link6" />
    <axis xyz="0 0 1" />
    <limit acceleration="2" effort="10" jerk="12" lower="-0.785398163" upper="0.785398163"
      velocity="1.5" />
    <dynamics damping="0" friction="0" />
  </joint>
  <link name="right_arm_link7">
    <inertial>
      <origin rpy="0 0 0" xyz="-0.03291 0.00799 -0.00131" />
      <mass value="0.6" />
      <inertia ixx="0.00124" ixy="0.00030" ixz="0.00013" iyy="0.00198" iyz="0.00007" izz="0.00164" />
    </inertial>
    <visual>
      <origin rpy="0 0 0" xyz="0 0 0" />
      <geometry>
        <mesh filename="meshes/arm/right_arm_link7.obj" />
      </geometry>
    </visual>
    <collision>
      <origin rpy="0 0 0" xyz="0 0 0" />
      <geometry>
        <mesh filename="meshes/arm/right_arm_link7.stl" />
      </geometry>
    </collision>
  </link>
  <joint name="right_arm_joint7" type="revolute">
    <origin rpy="-1.5707963267948966 0 0" xyz="0 0 0" />
    <parent link="right_arm_link6" />
    <child link="right_arm_link7" />
    <axis xyz="0 0 1" />
    <limit acceleration="2" effort="10" jerk="12" lower="-1.4" upper="1.4" velocity="1.5" />
    <dynamics damping="0" friction="0" />
  </joint>
  <link name="right_arm_end_effector_mount_link">
    <inertial>
      <origin rpy="0 0 0" xyz="0 0 0" />
      <mass value="0" />
      <inertia ixx="0" ixy="0" ixz="0" iyy="0" iyz="0" izz="0" />
    </inertial>
  </link>
  <joint name="right_arm_end_effector_mount_joint" type="fixed">
    <origin rpy="1.5707963267948966 0 3.141592653589793" xyz="-0.083 0 0" />
    <parent link="right_arm_link7" />
    <child link="right_arm_end_effector_mount_link" />
    <axis xyz="0 0 0" />
  </joint>
  <link name="right_gripper_camera_link">
    <visual>
      <geometry>
        <mesh filename="meshes/gripper/robotiq_gripper/visual/2f_85/d405_camera_link.obj" />
      </geometry>
    </visual>
    <collision>
      <geometry>
        <mesh
          filename="meshes/gripper/robotiq_gripper/collision/2f_85/d405_camera_link_convex_decomposition/d405_camera_link_collision_0.obj" />
      </geometry>
    </collision>
    <collision>
      <geometry>
        <mesh
          filename="meshes/gripper/robotiq_gripper/collision/2f_85/d405_camera_link_convex_decomposition/d405_camera_link_collision_1.obj" />
      </geometry>
    </collision>
    <collision>
      <geometry>
        <mesh
          filename="meshes/gripper/robotiq_gripper/collision/2f_85/d405_camera_link_convex_decomposition/d405_camera_link_collision_2.obj" />
      </geometry>
    </collision>
    <collision>
      <geometry>
        <mesh
          filename="meshes/gripper/robotiq_gripper/collision/2f_85/d405_camera_link_convex_decomposition/d405_camera_link_collision_3.obj" />
      </geometry>
    </collision>
    <collision>
      <geometry>
        <mesh
          filename="meshes/gripper/robotiq_gripper/collision/2f_85/d405_camera_link_convex_decomposition/d405_camera_link_collision_4.obj" />
      </geometry>
    </collision>
    <collision>
      <geometry>
        <mesh
          filename="meshes/gripper/robotiq_gripper/collision/2f_85/d405_camera_link_convex_decomposition/d405_camera_link_collision_5.obj" />
      </geometry>
    </collision>
    <collision>
      <geometry>
        <mesh
          filename="meshes/gripper/robotiq_gripper/collision/2f_85/d405_camera_link_convex_decomposition/d405_camera_link_collision_6.obj" />
      </geometry>
    </collision>
    <collision>
      <geometry>
        <mesh
          filename="meshes/gripper/robotiq_gripper/collision/2f_85/d405_camera_link_convex_decomposition/d405_camera_link_collision_7.obj" />
      </geometry>
    </collision>
    <collision>
      <geometry>
        <mesh
          filename="meshes/gripper/robotiq_gripper/collision/2f_85/d405_camera_link_convex_decomposition/d405_camera_link_collision_8.obj" />
      </geometry>
    </collision>
    <collision>
      <geometry>
        <mesh
          filename="meshes/gripper/robotiq_gripper/collision/2f_85/d405_camera_link_convex_decomposition/d405_camera_link_collision_9.obj" />
      </geometry>
    </collision>
    <collision>
      <geometry>
        <mesh
          filename="meshes/gripper/robotiq_gripper/collision/2f_85/d405_camera_link_convex_decomposition/d405_camera_link_collision_10.obj" />
      </geometry>
    </collision>
    <collision>
      <geometry>
        <mesh
          filename="meshes/gripper/robotiq_gripper/collision/2f_85/d405_camera_link_convex_decomposition/d405_camera_link_collision_11.obj" />
      </geometry>
    </collision>
    <collision>
      <geometry>
        <mesh
          filename="meshes/gripper/robotiq_gripper/collision/2f_85/d405_camera_link_convex_decomposition/d405_camera_link_collision_12.obj" />
      </geometry>
    </collision>
    <collision>
      <geometry>
        <mesh
          filename="meshes/gripper/robotiq_gripper/collision/2f_85/d405_camera_link_convex_decomposition/d405_camera_link_collision_13.obj" />
      </geometry>
    </collision>
    <collision>
      <geometry>
        <mesh
          filename="meshes/gripper/robotiq_gripper/collision/2f_85/d405_camera_link_convex_decomposition/d405_camera_link_collision_14.obj" />
      </geometry>
    </collision>
    <collision>
      <geometry>
        <mesh
          filename="meshes/gripper/robotiq_gripper/collision/2f_85/d405_camera_link_convex_decomposition/d405_camera_link_collision_15.obj" />
      </geometry>
    </collision>
    <collision>
      <geometry>
        <mesh
          filename="meshes/gripper/robotiq_gripper/collision/2f_85/d405_camera_link_convex_decomposition/d405_camera_link_collision_16.obj" />
      </geometry>
    </collision>
    <collision>
      <geometry>
        <mesh
          filename="meshes/gripper/robotiq_gripper/collision/2f_85/d405_camera_link_convex_decomposition/d405_camera_link_collision_17.obj" />
      </geometry>
    </collision>
    <collision>
      <geometry>
        <mesh
          filename="meshes/gripper/robotiq_gripper/collision/2f_85/d405_camera_link_convex_decomposition/d405_camera_link_collision_18.obj" />
      </geometry>
    </collision>
    <collision>
      <geometry>
        <mesh
          filename="meshes/gripper/robotiq_gripper/collision/2f_85/d405_camera_link_convex_decomposition/d405_camera_link_collision_19.obj" />
      </geometry>
    </collision>
    <collision>
      <geometry>
        <mesh
          filename="meshes/gripper/robotiq_gripper/collision/2f_85/d405_camera_link_convex_decomposition/d405_camera_link_collision_20.obj" />
      </geometry>
    </collision>
    <collision>
      <geometry>
        <mesh
          filename="meshes/gripper/robotiq_gripper/collision/2f_85/d405_camera_link_convex_decomposition/d405_camera_link_collision_21.obj" />
      </geometry>
    </collision>
    <collision>
      <geometry>
        <mesh
          filename="meshes/gripper/robotiq_gripper/collision/2f_85/d405_camera_link_convex_decomposition/d405_camera_link_collision_22.obj" />
      </geometry>
    </collision>
    <collision>
      <geometry>
        <mesh
          filename="meshes/gripper/robotiq_gripper/collision/2f_85/d405_camera_link_convex_decomposition/d405_camera_link_collision_23.obj" />
      </geometry>
    </collision>
    <collision>
      <geometry>
        <mesh
          filename="meshes/gripper/robotiq_gripper/collision/2f_85/d405_camera_link_convex_decomposition/d405_camera_link_collision_24.obj" />
      </geometry>
    </collision>
    <collision>
      <geometry>
        <mesh
          filename="meshes/gripper/robotiq_gripper/collision/2f_85/d405_camera_link_convex_decomposition/d405_camera_link_collision_25.obj" />
      </geometry>
    </collision>
    <collision>
      <geometry>
        <mesh
          filename="meshes/gripper/robotiq_gripper/collision/2f_85/d405_camera_link_convex_decomposition/d405_camera_link_collision_26.obj" />
      </geometry>
    </collision>
    <collision>
      <geometry>
        <mesh
          filename="meshes/gripper/robotiq_gripper/collision/2f_85/d405_camera_link_convex_decomposition/d405_camera_link_collision_27.obj" />
      </geometry>
    </collision>
    <collision>
      <geometry>
        <mesh
          filename="meshes/gripper/robotiq_gripper/collision/2f_85/d405_camera_link_convex_decomposition/d405_camera_link_collision_28.obj" />
      </geometry>
    </collision>
    <collision>
      <geometry>
        <mesh
          filename="meshes/gripper/robotiq_gripper/collision/2f_85/d405_camera_link_convex_decomposition/d405_camera_link_collision_29.obj" />
      </geometry>
    </collision>
    <collision>
      <geometry>
        <mesh
          filename="meshes/gripper/robotiq_gripper/collision/2f_85/d405_camera_link_convex_decomposition/d405_camera_link_collision_30.obj" />
      </geometry>
    </collision>
    <collision>
      <geometry>
        <mesh
          filename="meshes/gripper/robotiq_gripper/collision/2f_85/d405_camera_link_convex_decomposition/d405_camera_link_collision_31.obj" />
      </geometry>
    </collision>
    <collision>
      <geometry>
        <mesh
          filename="meshes/gripper/robotiq_gripper/collision/2f_85/d405_camera_link_convex_decomposition/d405_camera_link_collision_32.obj" />
      </geometry>
    </collision>
  </link>
  <link name="right_gripper_galbot_to_robotiq_adapter_link">
    <inertial>
      <origin rpy="0 0 0" xyz="-1.9028E-07 5.9618E-18 -0.0041416" />
      <mass value="0.023056" />
      <inertia ixx="5.5937E-06" ixy="-4.3322E-08" ixz="2.321E-10" iyy="5.3172E-06" iyz="1.9904E-12"
        izz="1.0645E-05" />
    </inertial>
    <visual>
      <origin rpy="0 0 0" xyz="0 0 0" />
      <geometry>
        <mesh filename="meshes/gripper/robotiq_gripper/visual/2f_85/galbot_to_robotiq_adapter.obj" />
      </geometry>
    </visual>
    <collision>
      <origin rpy="0 0 0" xyz="0 0 0" />
      <geometry>
        <mesh
          filename="meshes/gripper/robotiq_gripper/collision/2f_85/galbot_to_robotiq_adapter_convex.stl" />
      </geometry>
    </collision>
  </link>
  <link name="right_gripper_robotiq_85_base_link">
    <visual>
      <geometry>
        <mesh filename="meshes/gripper/robotiq_gripper/visual/2f_85/robotiq_base.dae" />
      </geometry>
    </visual>
    <collision>
      <geometry>
        <mesh filename="meshes/gripper/robotiq_gripper/collision/2f_85/robotiq_base.stl" />
      </geometry>
    </collision>
    <inertial>
      <origin rpy="0 0 0" xyz="0.0 2.274e-05 0.03232288" />
      <mass value="6.6320197e-01" />
      <inertia ixx="5.1617816e-04" ixy="2.936e-8" ixz="0.0" iyy="5.8802208e-04" iyz="-3.2296e-7"
        izz="3.9462776e-04" />
    </inertial>
  </link>
  <link name="right_gripper_robotiq_85_left_knuckle_link">
    <visual>
      <geometry>
        <mesh filename="meshes/gripper/robotiq_gripper/visual/2f_85/left_knuckle.dae" />
      </geometry>
    </visual>
    <collision>
      <geometry>
        <mesh filename="meshes/gripper/robotiq_gripper/collision/2f_85/left_knuckle.stl" />
      </geometry>
    </collision>
    <inertial>
      <origin rpy="0 0 0" xyz="0.01213197 0.0002 -0.00058647" />
      <mass value="1.384773208e-02" />
      <inertia ixx="3.5232e-7" ixy="0.0" ixz="1.1744e-7" iyy="2.31944e-6" iyz="0" izz="2.23136e-6" />
    </inertial>
  </link>
  <link name="right_gripper_robotiq_85_right_knuckle_link">
    <visual>
      <geometry>
        <mesh filename="meshes/gripper/robotiq_gripper/visual/2f_85/right_knuckle.dae" />
      </geometry>
    </visual>
    <collision>
      <geometry>
        <mesh filename="meshes/gripper/robotiq_gripper/collision/2f_85/right_knuckle.stl" />
      </geometry>
    </collision>
    <inertial>
      <origin rpy="0 0 0" xyz="-0.01213197 0.0002 -0.00058647" />
      <mass value="1.384773208e-02" />
      <inertia ixx="3.5232e-7" ixy="0.0" ixz="-1.1744e-7" iyy="2.31944e-6" iyz="0.0"
        izz="2.23136e-6" />
    </inertial>
  </link>
  <link name="right_gripper_robotiq_85_left_finger_link">
    <visual>
      <geometry>
        <mesh filename="meshes/gripper/robotiq_gripper/visual/2f_85/left_finger.dae" />
      </geometry>
    </visual>
    <collision>
      <geometry>
        <mesh filename="meshes/gripper/robotiq_gripper/collision/2f_85/left_finger.stl" />
      </geometry>
    </collision>
    <inertial>
      <origin rpy="0 0 0" xyz="0.00346899 -0.00079447 0.01867121" />
      <mass value="4.260376752e-02" />
      <inertia ixx="1.385792000000000e-05" ixy="0.0" ixz="-2.17264e-06" iyy="1.183208e-05" iyz="0.0"
        izz="5.19672e-06" />
    </inertial>
  </link>
  <link name="right_gripper_robotiq_85_right_finger_link">
    <visual>
      <geometry>
        <mesh filename="meshes/gripper/robotiq_gripper/visual/2f_85/right_finger.dae" />
      </geometry>
    </visual>
    <collision>
      <geometry>
        <mesh filename="meshes/gripper/robotiq_gripper/collision/2f_85/right_finger.stl" />
      </geometry>
    </collision>
    <inertial>
      <origin rpy="0 0 0" xyz="-0.00346899 -5.53e-06 0.01867121" />
      <mass value="4.260376752000000e-02" />
      <inertia ixx="1.385792e-05" ixy="0.0" ixz="2.17264e-06" iyy="1.183208e-05" iyz="0.0"
        izz="5.19672e-06" />
    </inertial>
  </link>
  <link name="right_gripper_robotiq_85_left_inner_knuckle_link">
    <visual>
      <geometry>
        <mesh filename="meshes/gripper/robotiq_gripper/visual/2f_85/left_inner_knuckle.dae" />
      </geometry>
    </visual>
    <collision>
      <geometry>
        <mesh filename="meshes/gripper/robotiq_gripper/collision/2f_85/left_inner_knuckle.stl" />
      </geometry>
    </collision>
    <inertial>
      <origin rpy="0 0 0" xyz="0.01897699 0.00015001 0.02247101" />
      <mass value="2.969376448e-02" />
      <inertia ixx="9.57136e-06" ixy="0.0" ixz="-3.93424e-06" iyy="8.69056e-06" iyz="0.0"
        izz="8.19144e-06" />
    </inertial>
  </link>
  <link name="right_gripper_robotiq_85_right_inner_knuckle_link">
    <visual>
      <geometry>
        <mesh filename="meshes/gripper/robotiq_gripper/visual/2f_85/right_inner_knuckle.dae" />
      </geometry>
    </visual>
    <collision>
      <geometry>
        <mesh filename="meshes/gripper/robotiq_gripper/collision/2f_85/right_inner_knuckle.stl" />
      </geometry>
    </collision>
    <inertial>
      <origin rpy="0 0 0" xyz="-0.01926824 5.001e-05 0.02222178" />
      <mass value="2.969376448e-02" />
      <inertia ixx="9.42456e-06" ixy="0.0" ixz="3.9636e-06" iyy="8.69056e-06" iyz="0.0"
        izz="8.33824e-06" />
    </inertial>
  </link>
  <link name="right_gripper_robotiq_85_left_finger_tip_link">
    <visual>
      <geometry>
        <mesh filename="meshes/gripper/robotiq_gripper/visual/2f_85/left_finger_tip.obj" />
      </geometry>
    </visual>
    <collision>
      <geometry>
        <mesh
          filename="meshes/gripper/robotiq_gripper/collision/2f_85/left_finger_tip_convex_decomposition/left_finger_tip_collision_0.obj" />
      </geometry>
    </collision>
    <collision>
      <geometry>
        <mesh
          filename="meshes/gripper/robotiq_gripper/collision/2f_85/left_finger_tip_convex_decomposition/left_finger_tip_collision_1.obj" />
      </geometry>
    </collision>
    <collision>
      <geometry>
        <mesh
          filename="meshes/gripper/robotiq_gripper/collision/2f_85/left_finger_tip_convex_decomposition/left_finger_tip_collision_2.obj" />
      </geometry>
    </collision>
    <collision>
      <geometry>
        <mesh
          filename="meshes/gripper/robotiq_gripper/collision/2f_85/left_finger_tip_convex_decomposition/left_finger_tip_collision_3.obj" />
      </geometry>
    </collision>
    <collision>
      <geometry>
        <mesh
          filename="meshes/gripper/robotiq_gripper/collision/2f_85/left_finger_tip_convex_decomposition/left_finger_tip_collision_4.obj" />
      </geometry>
    </collision>
    <collision>
      <geometry>
        <mesh
          filename="meshes/gripper/robotiq_gripper/collision/2f_85/left_finger_tip_convex_decomposition/left_finger_tip_collision_5.obj" />
      </geometry>
    </collision>
    <collision>
      <geometry>
        <mesh
          filename="meshes/gripper/robotiq_gripper/collision/2f_85/left_finger_tip_convex_decomposition/left_finger_tip_collision_6.obj" />
      </geometry>
    </collision>
    <collision>
      <geometry>
        <mesh
          filename="meshes/gripper/robotiq_gripper/collision/2f_85/left_finger_tip_convex_decomposition/left_finger_tip_collision_7.obj" />
      </geometry>
    </collision>
    <collision>
      <geometry>
        <mesh
          filename="meshes/gripper/robotiq_gripper/collision/2f_85/left_finger_tip_convex_decomposition/left_finger_tip_collision_8.obj" />
      </geometry>
    </collision>
    <collision>
      <geometry>
        <mesh
          filename="meshes/gripper/robotiq_gripper/collision/2f_85/left_finger_tip_convex_decomposition/left_finger_tip_collision_9.obj" />
      </geometry>
    </collision>
    <inertial>
      <origin rpy="0 0 0" xyz="-0.01456706 -0.0008 0.01649701" />
      <mass value="4.268588744e-02" />
      <inertia ixx="1.048152e-05" ixy="0.0" ixz="3.5232e-6" iyy="1.197888e-05" iyz="0.0"
        izz="4.22784e-06" />
    </inertial>
  </link>
  <link name="right_gripper_robotiq_85_right_finger_tip_link">
    <visual>
      <geometry>
        <mesh filename="meshes/gripper/robotiq_gripper/visual/2f_85/right_finger_tip.obj" />
      </geometry>
    </visual>
    <collision>
      <geometry>
        <mesh
          filename="meshes/gripper/robotiq_gripper/collision/2f_85/right_finger_tip_convex_decomposition/right_finger_tip_collision_0.obj" />
      </geometry>
    </collision>
    <collision>
      <geometry>
        <mesh
          filename="meshes/gripper/robotiq_gripper/collision/2f_85/right_finger_tip_convex_decomposition/right_finger_tip_collision_1.obj" />
      </geometry>
    </collision>
    <collision>
      <geometry>
        <mesh
          filename="meshes/gripper/robotiq_gripper/collision/2f_85/right_finger_tip_convex_decomposition/right_finger_tip_collision_2.obj" />
      </geometry>
    </collision>
    <collision>
      <geometry>
        <mesh
          filename="meshes/gripper/robotiq_gripper/collision/2f_85/right_finger_tip_convex_decomposition/right_finger_tip_collision_3.obj" />
      </geometry>
    </collision>
    <collision>
      <geometry>
        <mesh
          filename="meshes/gripper/robotiq_gripper/collision/2f_85/right_finger_tip_convex_decomposition/right_finger_tip_collision_4.obj" />
      </geometry>
    </collision>
    <collision>
      <geometry>
        <mesh
          filename="meshes/gripper/robotiq_gripper/collision/2f_85/right_finger_tip_convex_decomposition/right_finger_tip_collision_5.obj" />
      </geometry>
    </collision>
    <collision>
      <geometry>
        <mesh
          filename="meshes/gripper/robotiq_gripper/collision/2f_85/right_finger_tip_convex_decomposition/right_finger_tip_collision_6.obj" />
      </geometry>
    </collision>
    <collision>
      <geometry>
        <mesh
          filename="meshes/gripper/robotiq_gripper/collision/2f_85/right_finger_tip_convex_decomposition/right_finger_tip_collision_7.obj" />
      </geometry>
    </collision>
    <collision>
      <geometry>
        <mesh
          filename="meshes/gripper/robotiq_gripper/collision/2f_85/right_finger_tip_convex_decomposition/right_finger_tip_collision_8.obj" />
      </geometry>
    </collision>
    <collision>
      <geometry>
        <mesh
          filename="meshes/gripper/robotiq_gripper/collision/2f_85/right_finger_tip_convex_decomposition/right_finger_tip_collision_9.obj" />
      </geometry>
    </collision>
    <collision>
      <geometry>
        <mesh
          filename="meshes/gripper/robotiq_gripper/collision/2f_85/right_finger_tip_convex_decomposition/right_finger_tip_collision_10.obj" />
      </geometry>
    </collision>
    <inertial>
      <origin rpy="0 0 0" xyz="0.01456706 5e-05 0.01649701" />
      <mass value="4.268588744e-02" />
      <inertia ixx="1.048152e-05" ixy="0.0" ixz="-3.5232e-06" iyy="1.197888e-05" iyz="0.0"
        izz="4.22784e-06" />
    </inertial>
  </link>
  <joint name="right_gripper_joint" type="fixed">
    <origin rpy="3.141592653589793 -1.5707963267948966 0" xyz="0.008 0 0" />
    <parent link="right_arm_end_effector_mount_link" />
    <child link="right_gripper_galbot_to_robotiq_adapter_link" />
  </joint>
  <joint name="right_gripper_camera_joint" type="fixed">
    <origin rpy="3.141592653589793 -1.5707963267948966 0" xyz="0.008 0 0" />
    <parent link="right_arm_end_effector_mount_link" />
    <child link="right_gripper_camera_link" />
  </joint>
  <joint name="right_gripper_galbot_to_robotiq_adapter_joint" type="fixed">
    <parent link="right_gripper_galbot_to_robotiq_adapter_link" />
    <child link="right_gripper_robotiq_85_base_link" />
    <origin rpy="0 0 0" xyz="0 0 0" />
    <axis xyz="0 0 0" />
  </joint>
  <joint name="right_gripper_robotiq_85_left_knuckle_joint" type="revolute">
    <parent link="right_gripper_robotiq_85_base_link" />
    <child link="right_gripper_robotiq_85_left_knuckle_link" />
    <axis xyz="0 1 0" />
    <origin rpy="0 0 0" xyz="0.03060114 0.0 0.05490452" />
    <limit effort="50" lower="-0.8" upper="0" velocity="0.5" />
    <mimic joint="right_gripper_robotiq_85_right_knuckle_joint" multiplier="-1" />
  </joint>
  <joint name="right_gripper_robotiq_85_right_knuckle_joint" type="revolute">
    <parent link="right_gripper_robotiq_85_base_link" />
    <child link="right_gripper_robotiq_85_right_knuckle_link" />
    <axis xyz="0 1 0" />
    <origin rpy="0 0 0" xyz="-0.03060114 0.0 0.05490452" />
    <limit effort="50" lower="0" upper="0.8" velocity="0.5" />
  </joint>
  <joint name="right_gripper_robotiq_85_left_finger_joint" type="fixed">
    <parent link="right_gripper_robotiq_85_left_knuckle_link" />
    <child link="right_gripper_robotiq_85_left_finger_link" />
    <origin rpy="0 0 0" xyz="0.03152616 0.0 -0.00376347" />
  </joint>
  <joint name="right_gripper_robotiq_85_right_finger_joint" type="fixed">
    <parent link="right_gripper_robotiq_85_right_knuckle_link" />
    <child link="right_gripper_robotiq_85_right_finger_link" />
    <origin rpy="0 0 0" xyz="-0.03152616 0.0 -0.00376347" />
  </joint>
  <joint name="right_gripper_robotiq_85_left_inner_knuckle_joint" type="continuous">
    <parent link="right_gripper_robotiq_85_base_link" />
    <child link="right_gripper_robotiq_85_left_inner_knuckle_link" />
    <axis xyz="0 1 0" />
    <origin rpy="0 0 0" xyz="0.0127 0.0 0.06142" />
    <limit effort="50" lower="-0.8" upper="0" velocity="0.5" />
    <mimic joint="right_gripper_robotiq_85_right_knuckle_joint" multiplier="-1" />
  </joint>
  <joint name="right_gripper_robotiq_85_right_inner_knuckle_joint" type="continuous">
    <parent link="right_gripper_robotiq_85_base_link" />
    <child link="right_gripper_robotiq_85_right_inner_knuckle_link" />
    <axis xyz="0 1 0" />
    <origin rpy="0 0 0" xyz="-0.0127 0.0 0.06142" />
    <limit effort="50" lower="0" upper="0.8" velocity="0.5" />
    <mimic joint="right_gripper_robotiq_85_right_knuckle_joint" multiplier="1" />
  </joint>
  <joint name="right_gripper_robotiq_85_left_finger_tip_joint" type="continuous">
    <parent link="right_gripper_robotiq_85_left_finger_link" />
    <child link="right_gripper_robotiq_85_left_finger_tip_link" />
    <axis xyz="0 1 0" />
    <origin rpy="0 0 0" xyz="0.00563134 0.0 0.04718515" />
    <limit effort="50" lower="0" upper="0.8" velocity="0.5" />
    <mimic joint="right_gripper_robotiq_85_right_knuckle_joint" multiplier="1" />
  </joint>
  <joint name="right_gripper_robotiq_85_right_finger_tip_joint" type="continuous">
    <parent link="right_gripper_robotiq_85_right_finger_link" />
    <child link="right_gripper_robotiq_85_right_finger_tip_link" />
    <axis xyz="0 1 0" />
    <origin rpy="0 0 0" xyz="-0.00563134 0.0 0.04718515" />
    <limit effort="50" lower="-0.8" upper="0" velocity="0.5" />
    <mimic joint="right_gripper_robotiq_85_right_knuckle_joint" multiplier="-1" />
  </joint>
  <!-- For tcp-->
  <link name="right_gripper_tcp_link" />
  <joint name="right_gripper_tcp_joint" type="fixed">
    <parent link="right_gripper_robotiq_85_base_link" />
    <child link="right_gripper_tcp_link" />
    <origin rpy="-1.5707963267948966 -1.5707963267948966 0" xyz="0.0 0.0 0.15" />
    <!-- 0.17084 is the distance between the gripper base link and the tcp link -->
  </joint>
  <joint name="left_arm_joint" type="fixed">
    <origin rpy="0 0 0" xyz="0 0 0" />
    <parent link="torso_left_arm_mount_link" />
    <child link="left_arm_base_link" />
  </joint>
  <link name="left_arm_base_link">
    <inertial>
      <origin rpy="0 0 0" xyz="-0.00037 -0.00006 -0.11407" />
      <mass value="0.9" />
      <inertia ixx="0.01248" ixy="0.00000" ixz="0.00003" iyy="0.01247" iyz="0.00003" izz="0.00056" />
    </inertial>
  </link>
  <link name="left_arm_link1">
    <inertial>
      <origin rpy="0 0 0" xyz="0.00000 0.00650 -0.01459" />
      <mass value="1.48" />
      <inertia ixx="0.00378" ixy="0.00000" ixz="0.00000" iyy="0.00460" iyz="0.00020" izz="0.00217" />
    </inertial>
    <visual>
      <origin rpy="0 0 0" xyz="0 0 0" />
      <geometry>
        <mesh filename="meshes/arm/left_arm_link1.obj" />
      </geometry>
    </visual>
    <collision>
      <origin rpy="0 0 0" xyz="0 0 0" />
      <geometry>
        <mesh filename="meshes/arm/left_arm_link1.stl" />
      </geometry>
    </collision>
  </link>
  <joint name="left_arm_joint1" type="revolute">
    <origin rpy="0 0 0" xyz="0 0 0" />
    <parent link="left_arm_base_link" />
    <child link="left_arm_link1" />
    <axis xyz="0 0 1" />
    <limit acceleration="2" effort="60" jerk="12" lower="-3" upper="3" velocity="1.5" />
    <dynamics damping="0" friction="0" />
  </joint>
  <link name="left_arm_link2">
    <inertial>
      <origin rpy="0 0 0" xyz="-0.00080 0.09873 0.00815" />
      <mass value="1.33" />
      <inertia ixx="0.01827" ixy="0.00003" ixz="0.00003" iyy="0.00232" iyz="0.00134" izz="0.01769" />
    </inertial>
    <visual>
      <origin rpy="0 0 0" xyz="0 0 0" />
      <geometry>
        <mesh filename="meshes/arm/left_arm_link2.obj" />
      </geometry>
    </visual>
    <collision>
      <origin rpy="0 0 0" xyz="0 0 0" />
      <geometry>
        <mesh filename="meshes/arm/left_arm_link2.stl" />
      </geometry>
    </collision>
  </link>
  <joint name="left_arm_joint2" type="revolute">
    <origin rpy="1.5707963267948966 0 3.141592653589793" xyz="0 0 0" />
    <parent link="left_arm_link1" />
    <child link="left_arm_link2" />
    <axis xyz="0 0 1" />
    <limit acceleration="2" effort="60" jerk="12" lower="-1.7" upper="1.5707963267948966"
      velocity="1.5" />
    <dynamics damping="0" friction="0" />
  </joint>
  <link name="left_arm_link3">
    <inertial>
      <origin rpy="0 0 0" xyz="0.00019 0.00330 -0.04824" />
      <mass value="1.25" />
      <inertia ixx="0.00955" ixy="0.00000" ixz="0.00001" iyy="0.00983" iyz="0.00007" izz="0.00151" />
    </inertial>
    <visual>
      <origin rpy="0 0 0" xyz="0 0 0" />
      <geometry>
        <mesh filename="meshes/arm/left_arm_link3.obj" />
      </geometry>
    </visual>
    <collision>
      <origin rpy="0 0 0" xyz="0 0 0" />
      <geometry>
        <mesh filename="meshes/arm/left_arm_link3.stl" />
      </geometry>
    </collision>
  </link>
  <joint name="left_arm_joint3" type="revolute">
    <origin rpy="-1.5707963267948966 -1.5707963267948966 0" xyz="0 0.35 0" />
    <parent link="left_arm_link2" />
    <child link="left_arm_link3" />
    <axis xyz="0 0 1" />
    <limit acceleration="2" effort="30" jerk="12" lower="-2.9" upper="2.9" velocity="1.5" />
    <dynamics damping="0" friction="0" />
  </joint>
  <link name="left_arm_link4">
    <inertial>
      <origin rpy="0 0 0" xyz="0.00000 0.06457 0.00899" />
      <mass value="0.8" />
      <inertia ixx="0.00529" ixy="0.00000" ixz="0.00000" iyy="0.00120" iyz="0.00030" izz="0.00488" />
    </inertial>
    <visual>
      <origin rpy="0 0 0" xyz="0 0 0" />
      <geometry>
        <mesh filename="meshes/arm/left_arm_link4.obj" />
      </geometry>
    </visual>
    <collision>
      <origin rpy="0 0 0" xyz="0 0 0" />
      <geometry>
        <mesh filename="meshes/arm/left_arm_link4.stl" />
      </geometry>
    </collision>
  </link>
  <joint name="left_arm_joint4" type="revolute">
    <origin rpy="1.5707963267948966 0 -3.141592653589793" xyz="0 0 0" />
    <parent link="left_arm_link3" />
    <child link="left_arm_link4" />
    <axis xyz="0 0 1" />
    <limit acceleration="2" effort="30" jerk="12" lower="-2.1" upper="2.1" velocity="1.5" />
    <dynamics damping="0" friction="0" />
  </joint>
  <link name="left_arm_link5">
    <inertial>
      <origin rpy="0 0 0" xyz="-0.00201 0.00042 -0.14589" />
      <mass value="1.22" />
      <inertia ixx="0.03428" ixy="0.00001" ixz="0.00039" iyy="0.03366" iyz="0.00010" izz="0.00222" />
    </inertial>
    <visual>
      <origin rpy="0 0 0" xyz="0 0 0" />
      <geometry>
        <mesh filename="meshes/arm/left_arm_link5.obj" />
      </geometry>
    </visual>
    <collision>
      <origin rpy="0 0 0" xyz="0 0 0" />
      <geometry>
        <mesh filename="meshes/arm/left_arm_link5.stl" />
      </geometry>
    </collision>
  </link>
  <joint name="left_arm_joint5" type="revolute">
    <origin rpy="-1.5707963267948966 3.141592653589793 0" xyz="0 0.36 0" />
    <parent link="left_arm_link4" />
    <child link="left_arm_link5" />
    <axis xyz="0 0 1" />
    <limit acceleration="2" effort="10" jerk="12" lower="-2.9" upper="2.9" velocity="1.5" />
    <dynamics damping="0" friction="0" />
  </joint>
  <link name="left_arm_link6">
    <inertial>
      <origin rpy="0 0 0" xyz="0.00000 -0.01031 0.00000" />
      <mass value="0.43" />
      <inertia ixx="0.00051" ixy="0.00000" ixz="0.00000" iyy="0.00070" iyz="0.00000" izz="0.00091" />
    </inertial>
    <visual>
      <origin rpy="0 0 0" xyz="0 0 0" />
      <geometry>
        <mesh filename="meshes/arm/left_arm_link6.obj" />
      </geometry>
    </visual>
    <collision>
      <origin rpy="0 0 0" xyz="0 0 0" />
      <geometry>
        <mesh filename="meshes/arm/left_arm_link6.stl" />
      </geometry>
    </collision>
  </link>
  <joint name="left_arm_joint6" type="revolute">
    <origin rpy="1.5707963267948966 1.5707963267948966 0" xyz="0 0 0" />
    <parent link="left_arm_link5" />
    <child link="left_arm_link6" />
    <axis xyz="0 0 1" />
    <limit acceleration="2" effort="10" jerk="12" lower="-0.785398163" upper="0.785398163"
      velocity="1.5" />
    <dynamics damping="0" friction="0" />
  </joint>
  <link name="left_arm_link7">
    <inertial>
      <origin rpy="0 0 0" xyz="-0.03291 0.00799 -0.00131" />
      <mass value="0.6" />
      <inertia ixx="0.00124" ixy="0.00000" ixz="0.00012" iyy="0.00197" iyz="0.00004" izz="0.00165" />
    </inertial>
    <visual>
      <origin rpy="0 0 0" xyz="0 0 0" />
      <geometry>
        <mesh filename="meshes/arm/left_arm_link7.obj" />
      </geometry>
    </visual>
    <collision>
      <origin rpy="0 0 0" xyz="0 0 0" />
      <geometry>
        <mesh filename="meshes/arm/left_arm_link7.stl" />
      </geometry>
    </collision>
  </link>
  <joint name="left_arm_joint7" type="revolute">
    <origin rpy="1.5707963267948966 0 0" xyz="0 0 0" />
    <parent link="left_arm_link6" />
    <child link="left_arm_link7" />
    <axis xyz="0 0 1" />
    <limit acceleration="2" effort="10" jerk="12" lower="-1.4" upper="1.4" velocity="1.5" />
    <dynamics damping="0" friction="0" />
  </joint>
  <link name="left_arm_end_effector_mount_link">
    <inertial>
      <origin rpy="0 0 0" xyz="0 0 0" />
      <mass value="0" />
      <inertia ixx="0" ixy="0" ixz="0" iyy="0" iyz="0" izz="0" />
    </inertial>
  </link>
  <joint name="left_arm_end_effector_mount_joint" type="fixed">
    <origin rpy="-1.5707963267948966 0 3.141592653589793" xyz="-0.083 0 0" />
    <parent link="left_arm_link7" />
    <child link="left_arm_end_effector_mount_link" />
    <axis xyz="0 0 0" />
  </joint>
  <link name="left_gripper_camera_link">
    <visual>
      <geometry>
        <mesh filename="meshes/gripper/robotiq_gripper/visual/2f_85/d405_camera_link.obj" />
      </geometry>
    </visual>
    <collision>
      <geometry>
        <mesh
          filename="meshes/gripper/robotiq_gripper/collision/2f_85/d405_camera_link_convex_decomposition/d405_camera_link_collision_0.obj" />
      </geometry>
    </collision>
    <collision>
      <geometry>
        <mesh
          filename="meshes/gripper/robotiq_gripper/collision/2f_85/d405_camera_link_convex_decomposition/d405_camera_link_collision_1.obj" />
      </geometry>
    </collision>
    <collision>
      <geometry>
        <mesh
          filename="meshes/gripper/robotiq_gripper/collision/2f_85/d405_camera_link_convex_decomposition/d405_camera_link_collision_2.obj" />
      </geometry>
    </collision>
    <collision>
      <geometry>
        <mesh
          filename="meshes/gripper/robotiq_gripper/collision/2f_85/d405_camera_link_convex_decomposition/d405_camera_link_collision_3.obj" />
      </geometry>
    </collision>
    <collision>
      <geometry>
        <mesh
          filename="meshes/gripper/robotiq_gripper/collision/2f_85/d405_camera_link_convex_decomposition/d405_camera_link_collision_4.obj" />
      </geometry>
    </collision>
    <collision>
      <geometry>
        <mesh
          filename="meshes/gripper/robotiq_gripper/collision/2f_85/d405_camera_link_convex_decomposition/d405_camera_link_collision_5.obj" />
      </geometry>
    </collision>
    <collision>
      <geometry>
        <mesh
          filename="meshes/gripper/robotiq_gripper/collision/2f_85/d405_camera_link_convex_decomposition/d405_camera_link_collision_6.obj" />
      </geometry>
    </collision>
    <collision>
      <geometry>
        <mesh
          filename="meshes/gripper/robotiq_gripper/collision/2f_85/d405_camera_link_convex_decomposition/d405_camera_link_collision_7.obj" />
      </geometry>
    </collision>
    <collision>
      <geometry>
        <mesh
          filename="meshes/gripper/robotiq_gripper/collision/2f_85/d405_camera_link_convex_decomposition/d405_camera_link_collision_8.obj" />
      </geometry>
    </collision>
    <collision>
      <geometry>
        <mesh
          filename="meshes/gripper/robotiq_gripper/collision/2f_85/d405_camera_link_convex_decomposition/d405_camera_link_collision_9.obj" />
      </geometry>
    </collision>
    <collision>
      <geometry>
        <mesh
          filename="meshes/gripper/robotiq_gripper/collision/2f_85/d405_camera_link_convex_decomposition/d405_camera_link_collision_10.obj" />
      </geometry>
    </collision>
    <collision>
      <geometry>
        <mesh
          filename="meshes/gripper/robotiq_gripper/collision/2f_85/d405_camera_link_convex_decomposition/d405_camera_link_collision_11.obj" />
      </geometry>
    </collision>
    <collision>
      <geometry>
        <mesh
          filename="meshes/gripper/robotiq_gripper/collision/2f_85/d405_camera_link_convex_decomposition/d405_camera_link_collision_12.obj" />
      </geometry>
    </collision>
    <collision>
      <geometry>
        <mesh
          filename="meshes/gripper/robotiq_gripper/collision/2f_85/d405_camera_link_convex_decomposition/d405_camera_link_collision_13.obj" />
      </geometry>
    </collision>
    <collision>
      <geometry>
        <mesh
          filename="meshes/gripper/robotiq_gripper/collision/2f_85/d405_camera_link_convex_decomposition/d405_camera_link_collision_14.obj" />
      </geometry>
    </collision>
    <collision>
      <geometry>
        <mesh
          filename="meshes/gripper/robotiq_gripper/collision/2f_85/d405_camera_link_convex_decomposition/d405_camera_link_collision_15.obj" />
      </geometry>
    </collision>
    <collision>
      <geometry>
        <mesh
          filename="meshes/gripper/robotiq_gripper/collision/2f_85/d405_camera_link_convex_decomposition/d405_camera_link_collision_16.obj" />
      </geometry>
    </collision>
    <collision>
      <geometry>
        <mesh
          filename="meshes/gripper/robotiq_gripper/collision/2f_85/d405_camera_link_convex_decomposition/d405_camera_link_collision_17.obj" />
      </geometry>
    </collision>
    <collision>
      <geometry>
        <mesh
          filename="meshes/gripper/robotiq_gripper/collision/2f_85/d405_camera_link_convex_decomposition/d405_camera_link_collision_18.obj" />
      </geometry>
    </collision>
    <collision>
      <geometry>
        <mesh
          filename="meshes/gripper/robotiq_gripper/collision/2f_85/d405_camera_link_convex_decomposition/d405_camera_link_collision_19.obj" />
      </geometry>
    </collision>
    <collision>
      <geometry>
        <mesh
          filename="meshes/gripper/robotiq_gripper/collision/2f_85/d405_camera_link_convex_decomposition/d405_camera_link_collision_20.obj" />
      </geometry>
    </collision>
    <collision>
      <geometry>
        <mesh
          filename="meshes/gripper/robotiq_gripper/collision/2f_85/d405_camera_link_convex_decomposition/d405_camera_link_collision_21.obj" />
      </geometry>
    </collision>
    <collision>
      <geometry>
        <mesh
          filename="meshes/gripper/robotiq_gripper/collision/2f_85/d405_camera_link_convex_decomposition/d405_camera_link_collision_22.obj" />
      </geometry>
    </collision>
    <collision>
      <geometry>
        <mesh
          filename="meshes/gripper/robotiq_gripper/collision/2f_85/d405_camera_link_convex_decomposition/d405_camera_link_collision_23.obj" />
      </geometry>
    </collision>
    <collision>
      <geometry>
        <mesh
          filename="meshes/gripper/robotiq_gripper/collision/2f_85/d405_camera_link_convex_decomposition/d405_camera_link_collision_24.obj" />
      </geometry>
    </collision>
    <collision>
      <geometry>
        <mesh
          filename="meshes/gripper/robotiq_gripper/collision/2f_85/d405_camera_link_convex_decomposition/d405_camera_link_collision_25.obj" />
      </geometry>
    </collision>
    <collision>
      <geometry>
        <mesh
          filename="meshes/gripper/robotiq_gripper/collision/2f_85/d405_camera_link_convex_decomposition/d405_camera_link_collision_26.obj" />
      </geometry>
    </collision>
    <collision>
      <geometry>
        <mesh
          filename="meshes/gripper/robotiq_gripper/collision/2f_85/d405_camera_link_convex_decomposition/d405_camera_link_collision_27.obj" />
      </geometry>
    </collision>
    <collision>
      <geometry>
        <mesh
          filename="meshes/gripper/robotiq_gripper/collision/2f_85/d405_camera_link_convex_decomposition/d405_camera_link_collision_28.obj" />
      </geometry>
    </collision>
    <collision>
      <geometry>
        <mesh
          filename="meshes/gripper/robotiq_gripper/collision/2f_85/d405_camera_link_convex_decomposition/d405_camera_link_collision_29.obj" />
      </geometry>
    </collision>
    <collision>
      <geometry>
        <mesh
          filename="meshes/gripper/robotiq_gripper/collision/2f_85/d405_camera_link_convex_decomposition/d405_camera_link_collision_30.obj" />
      </geometry>
    </collision>
    <collision>
      <geometry>
        <mesh
          filename="meshes/gripper/robotiq_gripper/collision/2f_85/d405_camera_link_convex_decomposition/d405_camera_link_collision_31.obj" />
      </geometry>
    </collision>
    <collision>
      <geometry>
        <mesh
          filename="meshes/gripper/robotiq_gripper/collision/2f_85/d405_camera_link_convex_decomposition/d405_camera_link_collision_32.obj" />
      </geometry>
    </collision>
  </link>
  <link name="left_gripper_galbot_to_robotiq_adapter_link">
    <inertial>
      <origin rpy="0 0 0" xyz="-1.9028E-07 5.9618E-18 -0.0041416" />
      <mass value="0.023056" />
      <inertia ixx="5.5937E-06" ixy="-4.3322E-08" ixz="2.321E-10" iyy="5.3172E-06" iyz="1.9904E-12"
        izz="1.0645E-05" />
    </inertial>
    <visual>
      <origin rpy="0 0 0" xyz="0 0 0" />
      <geometry>
        <mesh filename="meshes/gripper/robotiq_gripper/visual/2f_85/galbot_to_robotiq_adapter.obj" />
      </geometry>
    </visual>
    <collision>
      <origin rpy="0 0 0" xyz="0 0 0" />
      <geometry>
        <mesh
          filename="meshes/gripper/robotiq_gripper/collision/2f_85/galbot_to_robotiq_adapter_convex.stl" />
      </geometry>
    </collision>
  </link>
  <link name="left_gripper_robotiq_85_base_link">
    <visual>
      <geometry>
        <mesh filename="meshes/gripper/robotiq_gripper/visual/2f_85/robotiq_base.dae" />
      </geometry>
    </visual>
    <collision>
      <geometry>
        <mesh filename="meshes/gripper/robotiq_gripper/collision/2f_85/robotiq_base.stl" />
      </geometry>
    </collision>
    <inertial>
      <origin rpy="0 0 0" xyz="0.0 2.274e-05 0.03232288" />
      <mass value="6.6320197e-01" />
      <inertia ixx="5.1617816e-04" ixy="2.936e-8" ixz="0.0" iyy="5.8802208e-04" iyz="-3.2296e-7"
        izz="3.9462776e-04" />
    </inertial>
  </link>
  <link name="left_gripper_robotiq_85_left_knuckle_link">
    <visual>
      <geometry>
        <mesh filename="meshes/gripper/robotiq_gripper/visual/2f_85/left_knuckle.dae" />
      </geometry>
    </visual>
    <collision>
      <geometry>
        <mesh filename="meshes/gripper/robotiq_gripper/collision/2f_85/left_knuckle.stl" />
      </geometry>
    </collision>
    <inertial>
      <origin rpy="0 0 0" xyz="0.01213197 0.0002 -0.00058647" />
      <mass value="1.384773208e-02" />
      <inertia ixx="3.5232e-7" ixy="0.0" ixz="1.1744e-7" iyy="2.31944e-6" iyz="0" izz="2.23136e-6" />
    </inertial>
  </link>
  <link name="left_gripper_robotiq_85_right_knuckle_link">
    <visual>
      <geometry>
        <mesh filename="meshes/gripper/robotiq_gripper/visual/2f_85/right_knuckle.dae" />
      </geometry>
    </visual>
    <collision>
      <geometry>
        <mesh filename="meshes/gripper/robotiq_gripper/collision/2f_85/right_knuckle.stl" />
      </geometry>
    </collision>
    <inertial>
      <origin rpy="0 0 0" xyz="-0.01213197 0.0002 -0.00058647" />
      <mass value="1.384773208e-02" />
      <inertia ixx="3.5232e-7" ixy="0.0" ixz="-1.1744e-7" iyy="2.31944e-6" iyz="0.0"
        izz="2.23136e-6" />
    </inertial>
  </link>
  <link name="left_gripper_robotiq_85_left_finger_link">
    <visual>
      <geometry>
        <mesh filename="meshes/gripper/robotiq_gripper/visual/2f_85/left_finger.dae" />
      </geometry>
    </visual>
    <collision>
      <geometry>
        <mesh filename="meshes/gripper/robotiq_gripper/collision/2f_85/left_finger.stl" />
      </geometry>
    </collision>
    <inertial>
      <origin rpy="0 0 0" xyz="0.00346899 -0.00079447 0.01867121" />
      <mass value="4.260376752e-02" />
      <inertia ixx="1.385792000000000e-05" ixy="0.0" ixz="-2.17264e-06" iyy="1.183208e-05" iyz="0.0"
        izz="5.19672e-06" />
    </inertial>
  </link>
  <link name="left_gripper_robotiq_85_right_finger_link">
    <visual>
      <geometry>
        <mesh filename="meshes/gripper/robotiq_gripper/visual/2f_85/right_finger.dae" />
      </geometry>
    </visual>
    <collision>
      <geometry>
        <mesh filename="meshes/gripper/robotiq_gripper/collision/2f_85/right_finger.stl" />
      </geometry>
    </collision>
    <inertial>
      <origin rpy="0 0 0" xyz="-0.00346899 -5.53e-06 0.01867121" />
      <mass value="4.260376752000000e-02" />
      <inertia ixx="1.385792e-05" ixy="0.0" ixz="2.17264e-06" iyy="1.183208e-05" iyz="0.0"
        izz="5.19672e-06" />
    </inertial>
  </link>
  <link name="left_gripper_robotiq_85_left_inner_knuckle_link">
    <visual>
      <geometry>
        <mesh filename="meshes/gripper/robotiq_gripper/visual/2f_85/left_inner_knuckle.dae" />
      </geometry>
    </visual>
    <collision>
      <geometry>
        <mesh filename="meshes/gripper/robotiq_gripper/collision/2f_85/left_inner_knuckle.stl" />
      </geometry>
    </collision>
    <inertial>
      <origin rpy="0 0 0" xyz="0.01897699 0.00015001 0.02247101" />
      <mass value="2.969376448e-02" />
      <inertia ixx="9.57136e-06" ixy="0.0" ixz="-3.93424e-06" iyy="8.69056e-06" iyz="0.0"
        izz="8.19144e-06" />
    </inertial>
  </link>
  <link name="left_gripper_robotiq_85_right_inner_knuckle_link">
    <visual>
      <geometry>
        <mesh filename="meshes/gripper/robotiq_gripper/visual/2f_85/right_inner_knuckle.dae" />
      </geometry>
    </visual>
    <collision>
      <geometry>
        <mesh filename="meshes/gripper/robotiq_gripper/collision/2f_85/right_inner_knuckle.stl" />
      </geometry>
    </collision>
    <inertial>
      <origin rpy="0 0 0" xyz="-0.01926824 5.001e-05 0.02222178" />
      <mass value="2.969376448e-02" />
      <inertia ixx="9.42456e-06" ixy="0.0" ixz="3.9636e-06" iyy="8.69056e-06" iyz="0.0"
        izz="8.33824e-06" />
    </inertial>
  </link>
  <link name="left_gripper_robotiq_85_left_finger_tip_link">
    <visual>
      <geometry>
        <mesh filename="meshes/gripper/robotiq_gripper/visual/2f_85/left_finger_tip.obj" />
      </geometry>
    </visual>
    <collision>
      <geometry>
        <mesh
          filename="meshes/gripper/robotiq_gripper/collision/2f_85/left_finger_tip_convex_decomposition/left_finger_tip_collision_0.obj" />
      </geometry>
    </collision>
    <collision>
      <geometry>
        <mesh
          filename="meshes/gripper/robotiq_gripper/collision/2f_85/left_finger_tip_convex_decomposition/left_finger_tip_collision_1.obj" />
      </geometry>
    </collision>
    <collision>
      <geometry>
        <mesh
          filename="meshes/gripper/robotiq_gripper/collision/2f_85/left_finger_tip_convex_decomposition/left_finger_tip_collision_2.obj" />
      </geometry>
    </collision>
    <collision>
      <geometry>
        <mesh
          filename="meshes/gripper/robotiq_gripper/collision/2f_85/left_finger_tip_convex_decomposition/left_finger_tip_collision_3.obj" />
      </geometry>
    </collision>
    <collision>
      <geometry>
        <mesh
          filename="meshes/gripper/robotiq_gripper/collision/2f_85/left_finger_tip_convex_decomposition/left_finger_tip_collision_4.obj" />
      </geometry>
    </collision>
    <collision>
      <geometry>
        <mesh
          filename="meshes/gripper/robotiq_gripper/collision/2f_85/left_finger_tip_convex_decomposition/left_finger_tip_collision_5.obj" />
      </geometry>
    </collision>
    <collision>
      <geometry>
        <mesh
          filename="meshes/gripper/robotiq_gripper/collision/2f_85/left_finger_tip_convex_decomposition/left_finger_tip_collision_6.obj" />
      </geometry>
    </collision>
    <collision>
      <geometry>
        <mesh
          filename="meshes/gripper/robotiq_gripper/collision/2f_85/left_finger_tip_convex_decomposition/left_finger_tip_collision_7.obj" />
      </geometry>
    </collision>
    <collision>
      <geometry>
        <mesh
          filename="meshes/gripper/robotiq_gripper/collision/2f_85/left_finger_tip_convex_decomposition/left_finger_tip_collision_8.obj" />
      </geometry>
    </collision>
    <collision>
      <geometry>
        <mesh
          filename="meshes/gripper/robotiq_gripper/collision/2f_85/left_finger_tip_convex_decomposition/left_finger_tip_collision_9.obj" />
      </geometry>
    </collision>
    <inertial>
      <origin rpy="0 0 0" xyz="-0.01456706 -0.0008 0.01649701" />
      <mass value="4.268588744e-02" />
      <inertia ixx="1.048152e-05" ixy="0.0" ixz="3.5232e-6" iyy="1.197888e-05" iyz="0.0"
        izz="4.22784e-06" />
    </inertial>
  </link>
  <link name="left_gripper_robotiq_85_right_finger_tip_link">
    <visual>
      <geometry>
        <mesh filename="meshes/gripper/robotiq_gripper/visual/2f_85/right_finger_tip.obj" />
      </geometry>
    </visual>
    <collision>
      <geometry>
        <mesh
          filename="meshes/gripper/robotiq_gripper/collision/2f_85/right_finger_tip_convex_decomposition/right_finger_tip_collision_0.obj" />
      </geometry>
    </collision>
    <collision>
      <geometry>
        <mesh
          filename="meshes/gripper/robotiq_gripper/collision/2f_85/right_finger_tip_convex_decomposition/right_finger_tip_collision_1.obj" />
      </geometry>
    </collision>
    <collision>
      <geometry>
        <mesh
          filename="meshes/gripper/robotiq_gripper/collision/2f_85/right_finger_tip_convex_decomposition/right_finger_tip_collision_2.obj" />
      </geometry>
    </collision>
    <collision>
      <geometry>
        <mesh
          filename="meshes/gripper/robotiq_gripper/collision/2f_85/right_finger_tip_convex_decomposition/right_finger_tip_collision_3.obj" />
      </geometry>
    </collision>
    <collision>
      <geometry>
        <mesh
          filename="meshes/gripper/robotiq_gripper/collision/2f_85/right_finger_tip_convex_decomposition/right_finger_tip_collision_4.obj" />
      </geometry>
    </collision>
    <collision>
      <geometry>
        <mesh
          filename="meshes/gripper/robotiq_gripper/collision/2f_85/right_finger_tip_convex_decomposition/right_finger_tip_collision_5.obj" />
      </geometry>
    </collision>
    <collision>
      <geometry>
        <mesh
          filename="meshes/gripper/robotiq_gripper/collision/2f_85/right_finger_tip_convex_decomposition/right_finger_tip_collision_6.obj" />
      </geometry>
    </collision>
    <collision>
      <geometry>
        <mesh
          filename="meshes/gripper/robotiq_gripper/collision/2f_85/right_finger_tip_convex_decomposition/right_finger_tip_collision_7.obj" />
      </geometry>
    </collision>
    <collision>
      <geometry>
        <mesh
          filename="meshes/gripper/robotiq_gripper/collision/2f_85/right_finger_tip_convex_decomposition/right_finger_tip_collision_8.obj" />
      </geometry>
    </collision>
    <collision>
      <geometry>
        <mesh
          filename="meshes/gripper/robotiq_gripper/collision/2f_85/right_finger_tip_convex_decomposition/right_finger_tip_collision_9.obj" />
      </geometry>
    </collision>
    <collision>
      <geometry>
        <mesh
          filename="meshes/gripper/robotiq_gripper/collision/2f_85/right_finger_tip_convex_decomposition/right_finger_tip_collision_10.obj" />
      </geometry>
    </collision>
    <inertial>
      <origin rpy="0 0 0" xyz="0.01456706 5e-05 0.01649701" />
      <mass value="4.268588744e-02" />
      <inertia ixx="1.048152e-05" ixy="0.0" ixz="-3.5232e-06" iyy="1.197888e-05" iyz="0.0"
        izz="4.22784e-06" />
    </inertial>
  </link>
  <joint name="left_gripper_joint" type="fixed">
    <origin rpy="0 1.5707963267948966 0" xyz="0.008 0 0" />
    <parent link="left_arm_end_effector_mount_link" />
    <child link="left_gripper_galbot_to_robotiq_adapter_link" />
  </joint>
  <joint name="left_gripper_camera_joint" type="fixed">
    <origin rpy="0 1.5707963267948966 0" xyz="0.008 0 0" />
    <parent link="left_arm_end_effector_mount_link" />
    <child link="left_gripper_camera_link" />
  </joint>
  <joint name="left_gripper_galbot_to_robotiq_adapter_joint" type="fixed">
    <parent link="left_gripper_galbot_to_robotiq_adapter_link" />
    <child link="left_gripper_robotiq_85_base_link" />
    <origin rpy="0 0 0" xyz="0 0 0" />
    <axis xyz="0 0 0" />
  </joint>
  <joint name="left_gripper_robotiq_85_left_knuckle_joint" type="revolute">
    <parent link="left_gripper_robotiq_85_base_link" />
    <child link="left_gripper_robotiq_85_left_knuckle_link" />
    <axis xyz="0 1 0" />
    <origin rpy="0 0 0" xyz="0.03060114 0.0 0.05490452" />
    <limit effort="50" lower="-0.8" upper="0" velocity="0.5" />
    <mimic joint="left_gripper_robotiq_85_right_knuckle_joint" multiplier="-1" />
  </joint>
  <joint name="left_gripper_robotiq_85_right_knuckle_joint" type="revolute">
    <parent link="left_gripper_robotiq_85_base_link" />
    <child link="left_gripper_robotiq_85_right_knuckle_link" />
    <axis xyz="0 1 0" />
    <origin rpy="0 0 0" xyz="-0.03060114 0.0 0.05490452" />
    <limit effort="50" lower="0" upper="0.8" velocity="0.5" />
  </joint>
  <joint name="left_gripper_robotiq_85_left_finger_joint" type="fixed">
    <parent link="left_gripper_robotiq_85_left_knuckle_link" />
    <child link="left_gripper_robotiq_85_left_finger_link" />
    <origin rpy="0 0 0" xyz="0.03152616 0.0 -0.00376347" />
  </joint>
  <joint name="left_gripper_robotiq_85_right_finger_joint" type="fixed">
    <parent link="left_gripper_robotiq_85_right_knuckle_link" />
    <child link="left_gripper_robotiq_85_right_finger_link" />
    <origin rpy="0 0 0" xyz="-0.03152616 0.0 -0.00376347" />
  </joint>
  <joint name="left_gripper_robotiq_85_left_inner_knuckle_joint" type="continuous">
    <parent link="left_gripper_robotiq_85_base_link" />
    <child link="left_gripper_robotiq_85_left_inner_knuckle_link" />
    <axis xyz="0 1 0" />
    <origin rpy="0 0 0" xyz="0.0127 0.0 0.06142" />
    <limit effort="50" lower="-0.8" upper="0" velocity="0.5" />
    <mimic joint="left_gripper_robotiq_85_right_knuckle_joint" multiplier="-1" />
  </joint>
  <joint name="left_gripper_robotiq_85_right_inner_knuckle_joint" type="continuous">
    <parent link="left_gripper_robotiq_85_base_link" />
    <child link="left_gripper_robotiq_85_right_inner_knuckle_link" />
    <axis xyz="0 1 0" />
    <origin rpy="0 0 0" xyz="-0.0127 0.0 0.06142" />
    <limit effort="50" lower="0" upper="0.8" velocity="0.5" />
    <mimic joint="left_gripper_robotiq_85_right_knuckle_joint" multiplier="1" />
  </joint>
  <joint name="left_gripper_robotiq_85_left_finger_tip_joint" type="continuous">
    <parent link="left_gripper_robotiq_85_left_finger_link" />
    <child link="left_gripper_robotiq_85_left_finger_tip_link" />
    <axis xyz="0 1 0" />
    <origin rpy="0 0 0" xyz="0.00563134 0.0 0.04718515" />
    <limit effort="50" lower="0" upper="0.8" velocity="0.5" />
    <mimic joint="left_gripper_robotiq_85_right_knuckle_joint" multiplier="1" />
  </joint>
  <joint name="left_gripper_robotiq_85_right_finger_tip_joint" type="continuous">
    <parent link="left_gripper_robotiq_85_right_finger_link" />
    <child link="left_gripper_robotiq_85_right_finger_tip_link" />
    <axis xyz="0 1 0" />
    <origin rpy="0 0 0" xyz="-0.00563134 0.0 0.04718515" />
    <limit effort="50" lower="-0.8" upper="0" velocity="0.5" />
    <mimic joint="left_gripper_robotiq_85_right_knuckle_joint" multiplier="-1" />
  </joint>
  <!-- For tcp-->
  <link name="left_gripper_tcp_link" />
  <joint name="left_gripper_tcp_joint" type="fixed">
    <parent link="left_gripper_robotiq_85_base_link" />
    <child link="left_gripper_tcp_link" />
    <origin rpy="-1.5707963267948966 -1.5707963267948966 0" xyz="0.0 0.0 0.15" />
    <!-- 0.17084 is the distance between the gripper base link and the tcp link -->
  </joint>
</robot>