<?xml version='1.0' encoding='UTF-8'?>
<!-- 
#####################################################################################
#
# Copyright (c) 2023-2025 Galbot, Inc. All Rights Reserved.
#
# This software contains confidential and proprietary information of Galbot, Inc.
# ("Confidential Information"). You shall not disclose such Confidential Information
# and shall use it only in accordance with the terms of the license agreement you
# entered into with Galbot, Inc.
#
# UNAUTHORIZED COPYING, USE, OR DISTRIBUTION OF THIS SOFTWARE, OR ANY PORTION OR
# DERIVATIVE THEREOF, IS STRICTLY PROHIBITED. IF YOU HAVE RECEIVED THIS SOFTWARE IN
# ERROR, PLEASE NOTIFY GALBOT, INC. IMMEDIATELY AND DELETE IT FROM YOUR SYSTEM.
#
#####################################################################################
#
# Description: Xacro file for Galbot One Charlie left hand.
# Author: Herman Ye@Galbot, Yuhao Zeng@Galbot
#
#####################################################################################
-->
<robot xmlns:xacro="http://www.ros.org/wiki/xacro" name="galbot_left_hand2">
  <xacro:macro name="inertial_matrix" params="mass">
    <inertial>
      <mass value="${mass}"/>
      <inertia ixx="1.0" ixy="0.0" ixz="0.0" iyy="0.5" iyz="0.0" izz="1.0"/>
    </inertial>
  </xacro:macro>
  <xacro:macro name="Box_inertial_matrix" params="m l w h">
    <inertial>
      <mass value="${m}"/>
      <inertia ixx="${m*(h*h + l*l)/12}" ixy="0" ixz="0" iyy="${m*(w*w + l*l)/12}" iyz="0" izz="${m*(w*w + h*h)/12}"/>
    </inertial>
  </xacro:macro>
  <xacro:macro name="galbot_left_hand2" params="parent *origin name:=galbot_left_hand2">
    <xacro:property name="M_PI" value="3.1415926535897931"/>
    <xacro:property name="J2_LIMIT" value="1.38"/>

    <joint name="${name}_joint" type="fixed">
      <xacro:insert_block name="origin"/>
      <parent link="${parent}"/>
      <child link="${name}_base_link"/>
    </joint>
    <link name="${name}_base_link">
      <inertial>
        <origin xyz="0.00816960851936208 0.0636207065507103 -0.00018912841690469" rpy="0 0 0"/>
        <mass value="0.451358060978353"/>
        <inertia ixx="0.000498049990193903" ixy="3.29099036424034E-06" ixz="-9.01303519099725E-07" iyy="0.000253439658189704" iyz="2.93799411856234E-06" izz="0.000312927861798085"/>
      </inertial>
      <visual>
        <origin xyz="0 0 0" rpy="0 0 0"/>
        <geometry>
          <mesh filename="package://galbot_one_charlie_description/meshes/galbot_hand2/left_base_link.stl"/>
        </geometry>
        <material name="">
          <color rgba="1 1 1 1"/>
        </material>
      </visual>
      <collision>
        <origin xyz="0 0 0" rpy="0 0 0"/>
        <geometry>
          <mesh filename="package://galbot_one_charlie_description/meshes/galbot_hand2/left_base_link.stl"/>
        </geometry>
      </collision>
    </link>
    <link name="${name}_finger1_link1">
      <inertial>
        <origin xyz="0.00785832448435717 0.00132081849967757 0.00170040366418012" rpy="0 0 0"/>
        <mass value="0.00153891343724584"/>
        <inertia ixx="3.96940695067765E-08" ixy="-2.25605790919375E-09" ixz="-1.11534015358591E-08" iyy="7.00013902307812E-08" iyz="-6.31361887888073E-10" izz="5.73022005170989E-08"/>
      </inertial>
      <visual>
        <origin xyz="0 0 0" rpy="0 0 0"/>
        <geometry>
          <mesh filename="package://galbot_one_charlie_description/meshes/galbot_hand2/left_finger1_link1.stl"/>
        </geometry>
        <material name="">
          <color rgba="1 1 1 1"/>
        </material>
      </visual>
      <collision>
        <origin xyz="0 0 0" rpy="0 0 0"/>
        <geometry>
          <mesh filename="package://galbot_one_charlie_description/meshes/galbot_hand2/left_finger1_link1.stl"/>
        </geometry>
      </collision>
    </link>
    <joint name="${name}_finger1_joint1" type="revolute">
      <origin xyz="0.0555 -0.028 -0.017993" rpy="-1.5707963267949 0 -1.5707963267949"/>
      <parent link="${name}_base_link"/>
      <child link="${name}_finger1_link1"/>
      <axis xyz="0 0 1"/>
      <limit lower="0" upper="1.4454124" effort="10" velocity="1.5"/>
    </joint>
    <link name="${name}_finger1_link2">
      <inertial>
        <origin xyz="0.0296825612177022 0.00637937878751394 -8.43605438977102E-10" rpy="0 0 0"/>
        <mass value="0.00724797536837754"/>
        <inertia ixx="4.72588057392771E-07" ixy="7.05435365244983E-08" ixz="-1.09120906427536E-13" iyy="1.35886054864431E-06" iyz="1.21486244887893E-13" izz="1.81818536529581E-06"/>
      </inertial>
      <visual>
        <origin xyz="0 0 0" rpy="0 0 0"/>
        <geometry>
          <mesh filename="package://galbot_one_charlie_description/meshes/galbot_hand2/left_finger1_link2.stl"/>
        </geometry>
        <material name="">
          <color rgba="1 1 1 1"/>
        </material>
      </visual>
      <collision>
        <origin xyz="0 0 0" rpy="0 0 0"/>
        <geometry>
          <mesh filename="package://galbot_one_charlie_description/meshes/galbot_hand2/left_finger1_link2.stl"/>
        </geometry>
      </collision>
    </link>
    <joint name="${name}_finger1_joint2" type="revolute">
      <origin xyz="0.014916 0.0090836 -0.0007" rpy="1.5708 0 0.13459"/>
      <parent link="${name}_finger1_link1"/>
      <child link="${name}_finger1_link2"/>
      <axis xyz="0 0 1"/>
      <limit lower="0" upper="1.1961649" effort="10" velocity="1.5"/>
    </joint>
    <link name="${name}_finger1_link3">
      <inertial>
        <origin xyz="0.0171434284036376 -0.00150490214088548 -4.44054506498759E-08" rpy="0 0 0"/>
        <mass value="0.00474795122263958"/>
        <inertia ixx="2.72339609508888E-07" ixy="9.31861245911121E-08" ixz="-2.34651651392827E-13" iyy="3.73288445610006E-07" iyz="2.45287512165448E-13" izz="6.22247088985726E-07"/>
      </inertial>
      <visual>
        <origin xyz="0 0 0" rpy="0 0 0"/>
        <geometry>
          <mesh filename="package://galbot_one_charlie_description/meshes/galbot_hand2/left_finger1_link3.stl"/>
        </geometry>
        <material name="">
          <color rgba="1 1 1 1"/>
        </material>
      </visual>
      <collision>
        <origin xyz="0 0 0" rpy="0 0 0"/>
        <geometry>
          <mesh filename="package://galbot_one_charlie_description/meshes/galbot_hand2/left_finger1_link3.stl"/>
        </geometry>
      </collision>
    </link>
    <joint name="${name}_finger1_joint3" type="revolute">
      <origin xyz="0.050801 0.0048501 0" rpy="0 0 0"/>
      <parent link="${name}_finger1_link2"/>
      <child link="${name}_finger1_link3"/>
      <axis xyz="0 0 1"/>
      <limit lower="0" upper="0.9287205" effort="10" velocity="1.5"/>
    </joint>
    <link name="${name}_finger1_link4">
      <inertial>
        <origin xyz="0.0154993840945061 0.00400208159023535 2.97257485136482E-06" rpy="0 0 0"/>
        <mass value="0.00507768871509372"/>
        <inertia ixx="1.26734739246418E-07" ixy="5.68383791569981E-08" ixz="-7.39145180973407E-11" iyy="4.08272374697105E-07" iyz="2.9467226627009E-11" izz="3.49536217441572E-07"/>
      </inertial>
      <visual>
        <origin xyz="0 0 0" rpy="0 0 0"/>
        <geometry>
          <mesh filename="package://galbot_one_charlie_description/meshes/galbot_hand2/left_finger1_link4.stl"/>
        </geometry>
        <material name="">
          <color rgba="1 1 1 1"/>
        </material>
      </visual>
      <collision>
        <origin xyz="0 0 0" rpy="0 0 0"/>
        <geometry>
          <mesh filename="package://galbot_one_charlie_description/meshes/galbot_hand2/left_finger1_link4.stl"/>
        </geometry>
      </collision>
    </link>
    <joint name="${name}_finger1_joint4" type="revolute">
      <origin xyz="0.033461 -0.010517 0" rpy="0 0 0"/>
      <parent link="${name}_finger1_link3"/>
      <child link="${name}_finger1_link4"/>
      <axis xyz="0 0 1"/>
      <limit lower="0" upper="0.5928541" effort="10" velocity="1.5"/>
    </joint>
    <link name="${name}_finger1_end_effector_link"/>
    <joint name="${name}_finger1_end_effector_joint" type="fixed">
      <origin xyz="0.0238977384221158 0.0122047665173845 0" rpy="0 0 -0.166296781966088"/>
      <parent link="${name}_finger1_link4"/>
      <child link="${name}_finger1_end_effector_link"/>
      <axis xyz="0 0 0"/>
    </joint>
    <link name="${name}_finger2_link1">
      <inertial>
        <origin xyz="0.00382575221148437 -5.00520139917748E-09 -0.00379970728509158" rpy="0 0 0"/>
        <mass value="0.000889473582525137"/>
        <inertia ixx="4.0055788387694E-08" ixy="-1.56454747029463E-14" ixz="-4.38944911232404E-09" iyy="4.42763145564234E-08" iyz="-1.56506551122916E-14" izz="1.19540185771033E-08"/>
      </inertial>
      <visual>
        <origin xyz="0 0 0" rpy="0 0 0"/>
        <geometry>
          <mesh filename="package://galbot_one_charlie_description/meshes/galbot_hand2/left_finger2_link1.stl"/>
        </geometry>
        <material name="">
          <color rgba="1 1 1 1"/>
        </material>
      </visual>
      <collision>
        <origin xyz="0 0 0" rpy="0 0 0"/>
        <geometry>
          <mesh filename="package://galbot_one_charlie_description/meshes/galbot_hand2/left_finger2_link1.stl"/>
        </geometry>
      </collision>
    </link>
    <joint name="${name}_finger2_joint1" type="revolute">
      <origin xyz="0.1333 -0.0339 -0.0010932" rpy="3.14159265358979 0 0"/>
      <parent link="${name}_base_link"/>
      <child link="${name}_finger2_link1"/>
      <axis xyz="0 0 1"/>
      <limit lower="-0.34906585" upper="0.34906585" effort="10" velocity="1.5"/>
    </joint>
    <link name="${name}_finger2_link2">
      <inertial>
        <origin xyz="0.0199166121070695 0.00452784516743032 -0.000303877808472956" rpy="0 0 0"/>
        <mass value="0.00346834967811122"/>
        <inertia ixx="7.47882545674864E-08" ixy="-6.37999082906082E-08" ixz="-8.29444375307042E-09" iyy="6.28681619362614E-07" iyz="-4.51118940783156E-10" izz="6.89244310692081E-07"/>
      </inertial>
      <visual>
        <origin xyz="0 0 0" rpy="0 0 0"/>
        <geometry>
          <mesh filename="package://galbot_one_charlie_description/meshes/galbot_hand2/left_finger2_link2.stl"/>
        </geometry>
        <material name="">
          <color rgba="1 1 1 1"/>
        </material>
      </visual>
      <collision>
        <origin xyz="0 0 0" rpy="0 0 0"/>
        <geometry>
          <mesh filename="package://galbot_one_charlie_description/meshes/galbot_hand2/left_finger2_link2.stl"/>
        </geometry>
      </collision>
    </link>
    <joint name="${name}_finger2_joint2" type="revolute">
      <origin xyz="0.00510000000000004 0 0.00439999999999952" rpy="1.5707963267949 0 0"/>
      <parent link="${name}_finger2_link1"/>
      <child link="${name}_finger2_link2"/>
      <axis xyz="0 0 1"/>
      <limit lower="0" upper="${J2_LIMIT}" effort="10" velocity="1.5"/>
    </joint>
    <link name="${name}_finger2_link3">
      <inertial>
        <origin xyz="0.0131841948791408 0.000998392629336252 -4.43775828881388E-05" rpy="0 0 0"/>
        <mass value="0.00240330669142529"/>
        <inertia ixx="9.21336766793984E-08" ixy="-6.73938389627133E-09" ixz="9.17491834587275E-09" iyy="2.61350743499042E-07" iyz="3.14135392902408E-09" izz="2.21858731660143E-07"/>
      </inertial>
      <visual>
        <origin xyz="0 0 0" rpy="0 0 0"/>
        <geometry>
          <mesh filename="package://galbot_one_charlie_description/meshes/galbot_hand2/left_finger2_link3.stl"/>
        </geometry>
        <material name="">
          <color rgba="1 1 1 1"/>
        </material>
      </visual>
      <collision>
        <origin xyz="0 0 0" rpy="0 0 0"/>
        <geometry>
          <mesh filename="package://galbot_one_charlie_description/meshes/galbot_hand2/left_finger2_link3.stl"/>
        </geometry>
      </collision>
    </link>
    <joint name="${name}_finger2_joint3" type="revolute">
      <origin xyz="0.0377 0.0057104 0" rpy="0 0 0"/>
      <parent link="${name}_finger2_link2"/>
      <child link="${name}_finger2_link3"/>
      <axis xyz="0 0 1"/>
      <limit lower="0" upper="${1.021*J2_LIMIT}" effort="10" velocity="1.5"/>
      <!-- <mimic joint="${name}_finger2_joint2" multiplier="1.021" offset="0"/> -->
    </joint>
    <link name="${name}_finger2_link4">
      <inertial>
        <origin xyz="0.0164013380865539 -0.000465187190866665 2.14248312125492E-06" rpy="0 0 0"/>
        <mass value="0.00413805450374486"/>
        <inertia ixx="1.20869219589551E-07" ixy="4.29725372551635E-08" ixz="8.81359189277686E-10" iyy="3.17049521027888E-07" iyz="-4.42801512142467E-10" izz="2.55560236671056E-07"/>
      </inertial>
      <visual>
        <origin xyz="0 0 0" rpy="0 0 0"/>
        <geometry>
          <mesh filename="package://galbot_one_charlie_description/meshes/galbot_hand2/left_finger2_link4.stl"/>
        </geometry>
        <material name="">
          <color rgba="1 1 1 1"/>
        </material>
      </visual>
      <collision>
        <origin xyz="0 0 0" rpy="0 0 0"/>
        <geometry>
          <mesh filename="package://galbot_one_charlie_description/meshes/galbot_hand2/left_finger2_link4.stl"/>
        </geometry>
      </collision>
    </link>
    <joint name="${name}_finger2_joint4" type="revolute">
      <origin xyz="0.0265 0 0" rpy="0 0 0"/>
      <parent link="${name}_finger2_link3"/>
      <child link="${name}_finger2_link4"/>
      <axis xyz="0 0 1"/>
      <limit lower="0" upper="${0.857*1.021*J2_LIMIT}" effort="10" velocity="1.5"/>
      <!-- <mimic joint="${name}_finger2_joint3" multiplier="0.857" offset="0"/> -->
    </joint>
    <link name="${name}_finger2_end_effector_link"/>
    <joint name="${name}_finger2_end_effector_joint" type="fixed">
      <origin xyz="0.021611 0.0063638 0" rpy="0 0 -0.12217"/>
      <parent link="${name}_finger2_link4"/>
      <child link="${name}_finger2_end_effector_link"/>
      <axis xyz="0 0 0"/>
    </joint>
    <link name="${name}_finger3_link1">
      <inertial>
        <origin xyz="0.00382575221148432 -5.00520138183025E-09 -0.00379970728509156" rpy="0 0 0"/>
        <mass value="0.000889473582525136"/>
        <inertia ixx="4.0055788387694E-08" ixy="-1.56454747080736E-14" ixz="-4.389449112324E-09" iyy="4.42763145564233E-08" iyz="-1.56506551211202E-14" izz="1.19540185771033E-08"/>
      </inertial>
      <visual>
        <origin xyz="0 0 0" rpy="0 0 0"/>
        <geometry>
          <mesh filename="package://galbot_one_charlie_description/meshes/galbot_hand2/left_finger3_link1.stl"/>
        </geometry>
        <material name="">
          <color rgba="1 1 1 1"/>
        </material>
      </visual>
      <collision>
        <origin xyz="0 0 0" rpy="0 0 0"/>
        <geometry>
          <mesh filename="package://galbot_one_charlie_description/meshes/galbot_hand2/left_finger3_link1.stl"/>
        </geometry>
      </collision>
    </link>
    <joint name="${name}_finger3_joint1" type="revolute">
      <origin xyz="0.1373 -0.0113 -0.0010932" rpy="3.14159265358979 0 0"/>
      <parent link="${name}_base_link"/>
      <child link="${name}_finger3_link1"/>
      <axis xyz="0 0 1"/>
      <limit lower="-0.34906585" upper="0.34906585" effort="10" velocity="1.5"/>
    </joint>
    <link name="${name}_finger3_link2">
      <inertial>
        <origin xyz="0.0199166121070695 0.00452784516743032 -0.000303877808472984" rpy="0 0 0"/>
        <mass value="0.00346834967811122"/>
        <inertia ixx="7.47882545674384E-08" ixy="-6.37999082906082E-08" ixz="-8.2944437530704E-09" iyy="6.28681619362615E-07" iyz="-4.51118940783142E-10" izz="6.89244310692035E-07"/>
      </inertial>
      <visual>
        <origin xyz="0 0 0" rpy="0 0 0"/>
        <geometry>
          <mesh filename="package://galbot_one_charlie_description/meshes/galbot_hand2/left_finger3_link2.stl"/>
        </geometry>
        <material name="">
          <color rgba="1 1 1 1"/>
        </material>
      </visual>
      <collision>
        <origin xyz="0 0 0" rpy="0 0 0"/>
        <geometry>
          <mesh filename="package://galbot_one_charlie_description/meshes/galbot_hand2/left_finger3_link2.stl"/>
        </geometry>
      </collision>
    </link>
    <joint name="${name}_finger3_joint2" type="revolute">
      <origin xyz="0.00509999999999999 0 0.00439999999999953" rpy="1.5707963267949 0 0"/>
      <parent link="${name}_finger3_link1"/>
      <child link="${name}_finger3_link2"/>
      <axis xyz="0 0 1"/>
      <limit lower="0" upper="${J2_LIMIT}" effort="10" velocity="1.5"/>
    </joint>
    <link name="${name}_finger3_link3">
      <inertial>
        <origin xyz="0.0131841948791408 0.000998392629336248 -4.43775828881717E-05" rpy="0 0 0"/>
        <mass value="0.00240330669142529"/>
        <inertia ixx="9.21336766793984E-08" ixy="-6.73938389627187E-09" ixz="9.17491834587279E-09" iyy="2.61350743499041E-07" iyz="3.14135392902406E-09" izz="2.21858731660142E-07"/>
      </inertial>
      <visual>
        <origin xyz="0 0 0" rpy="0 0 0"/>
        <geometry>
          <mesh filename="package://galbot_one_charlie_description/meshes/galbot_hand2/left_finger3_link3.stl"/>
        </geometry>
        <material name="">
          <color rgba="1 1 1 1"/>
        </material>
      </visual>
      <collision>
        <origin xyz="0 0 0" rpy="0 0 0"/>
        <geometry>
          <mesh filename="package://galbot_one_charlie_description/meshes/galbot_hand2/left_finger3_link3.stl"/>
        </geometry>
      </collision>
    </link>
    <joint name="${name}_finger3_joint3" type="revolute">
      <origin xyz="0.0376999618833714 0.00571036952345733 0" rpy="0 0 0"/>
      <parent link="${name}_finger3_link2"/>
      <child link="${name}_finger3_link3"/>
      <axis xyz="0 0 1"/>
      <limit lower="0" upper="${1.021*J2_LIMIT}" effort="10" velocity="1.5"/>
      <!-- <mimic joint="${name}_finger3_joint2" multiplier="1.021" offset="0"/> -->
    </joint>
    <link name="${name}_finger3_link4">
      <inertial>
        <origin xyz="0.016401338086554 -0.00046518719086669 2.14248312120288E-06" rpy="0 0 0"/>
        <mass value="0.00413805450374489"/>
        <inertia ixx="1.20869219589554E-07" ixy="4.29725372551654E-08" ixz="8.81359189278112E-10" iyy="3.1704952102789E-07" iyz="-4.42801512142491E-10" izz="2.5556023667106E-07"/>
      </inertial>
      <visual>
        <origin xyz="0 0 0" rpy="0 0 0"/>
        <geometry>
          <mesh filename="package://galbot_one_charlie_description/meshes/galbot_hand2/left_finger3_link4.stl"/>
        </geometry>
        <material name="">
          <color rgba="1 1 1 1"/>
        </material>
      </visual>
      <collision>
        <origin xyz="0 0 0" rpy="0 0 0"/>
        <geometry>
          <mesh filename="package://galbot_one_charlie_description/meshes/galbot_hand2/left_finger3_link4.stl"/>
        </geometry>
      </collision>
    </link>
    <joint name="${name}_finger3_joint4" type="revolute">
      <origin xyz="0.0265 0 0" rpy="0 0 0"/>
      <parent link="${name}_finger3_link3"/>
      <child link="${name}_finger3_link4"/>
      <axis xyz="0 0 1"/>
      <limit lower="0" upper="${0.857*1.021*J2_LIMIT}" effort="10" velocity="1.5"/>
      <!-- <mimic joint="${name}_finger3_joint3" multiplier="0.857" offset="0"/> -->
    </joint>
    <link name="${name}_finger3_end_effector_link"/>
    <joint name="${name}_finger3_end_effector_joint" type="fixed">
      <origin xyz="0.021610626928784 0.00636376159979386 0" rpy="0 0 -0.122173047637935"/>
      <parent link="${name}_finger3_link4"/>
      <child link="${name}_finger3_end_effector_link"/>
      <axis xyz="0 0 0"/>
    </joint>
    <link name="${name}_finger4_link1">
      <inertial>
        <origin xyz="0.0038257522114842 -5.00520198898347E-09 -0.00379970728509157" rpy="0 0 0"/>
        <mass value="0.000889473582525138"/>
        <inertia ixx="4.0055788387694E-08" ixy="-1.56454747150249E-14" ixz="-4.38944911232402E-09" iyy="4.42763145564234E-08" iyz="-1.5650655132107E-14" izz="1.19540185771033E-08"/>
      </inertial>
      <visual>
        <origin xyz="0 0 0" rpy="0 0 0"/>
        <geometry>
          <mesh filename="package://galbot_one_charlie_description/meshes/galbot_hand2/left_finger4_link1.stl"/>
        </geometry>
        <material name="">
          <color rgba="1 1 1 1"/>
        </material>
      </visual>
      <collision>
        <origin xyz="0 0 0" rpy="0 0 0"/>
        <geometry>
          <mesh filename="package://galbot_one_charlie_description/meshes/galbot_hand2/left_finger4_link1.stl"/>
        </geometry>
      </collision>
    </link>
    <joint name="${name}_finger4_joint1" type="revolute">
      <origin xyz="0.1358 0.0113 -0.0010932" rpy="3.14159265358979 0 0"/>
      <parent link="${name}_base_link"/>
      <child link="${name}_finger4_link1"/>
      <axis xyz="0 0 1"/>
      <limit lower="-0.34906585" upper="0.34906585" effort="10" velocity="1.5"/>
    </joint>
    <link name="${name}_finger4_link2">
      <inertial>
        <origin xyz="0.0199166121070696 0.00452784516743035 -0.000303877808472375" rpy="0 0 0"/>
        <mass value="0.00346834967811123"/>
        <inertia ixx="7.47882545673969E-08" ixy="-6.37999082906091E-08" ixz="-8.29444375307024E-09" iyy="6.28681619362616E-07" iyz="-4.5111894078301E-10" izz="6.89244310691995E-07"/>
      </inertial>
      <visual>
        <origin xyz="0 0 0" rpy="0 0 0"/>
        <geometry>
          <mesh filename="package://galbot_one_charlie_description/meshes/galbot_hand2/left_finger4_link2.stl"/>
        </geometry>
        <material name="">
          <color rgba="1 1 1 1"/>
        </material>
      </visual>
      <collision>
        <origin xyz="0 0 0" rpy="0 0 0"/>
        <geometry>
          <mesh filename="package://galbot_one_charlie_description/meshes/galbot_hand2/left_finger4_link2.stl"/>
        </geometry>
      </collision>
    </link>
    <joint name="${name}_finger4_joint2" type="revolute">
      <origin xyz="0.00509999999999987 0 0.00439999999999953" rpy="1.5707963267949 0 0"/>
      <parent link="${name}_finger4_link1"/>
      <child link="${name}_finger4_link2"/>
      <axis xyz="0 0 1"/>
      <limit lower="0" upper="${J2_LIMIT}" effort="10" velocity="1.5"/>
    </joint>
    <link name="${name}_finger4_link3">
      <inertial>
        <origin xyz="0.0131841948791408 0.000998392629336248 -4.43775828875594E-05" rpy="0 0 0"/>
        <mass value="0.00240330669142529"/>
        <inertia ixx="9.21336766794008E-08" ixy="-6.73938389627169E-09" ixz="9.17491834587288E-09" iyy="2.61350743499041E-07" iyz="3.14135392902408E-09" izz="2.21858731660145E-07"/>
      </inertial>
      <visual>
        <origin xyz="0 0 0" rpy="0 0 0"/>
        <geometry>
          <mesh filename="package://galbot_one_charlie_description/meshes/galbot_hand2/left_finger4_link3.stl"/>
        </geometry>
        <material name="">
          <color rgba="1 1 1 1"/>
        </material>
      </visual>
      <collision>
        <origin xyz="0 0 0" rpy="0 0 0"/>
        <geometry>
          <mesh filename="package://galbot_one_charlie_description/meshes/galbot_hand2/left_finger4_link3.stl"/>
        </geometry>
      </collision>
    </link>
    <joint name="${name}_finger4_joint3" type="revolute">
      <origin xyz="0.0376999618833714 0.00571036952345734 0" rpy="0 0 0"/>
      <parent link="${name}_finger4_link2"/>
      <child link="${name}_finger4_link3"/>
      <axis xyz="0 0 1"/>
      <limit lower="0" upper="${1.021*J2_LIMIT}" effort="10" velocity="1.5"/>
      <!-- <mimic joint="${name}_finger4_joint2" multiplier="1.021" offset="0"/> -->
    </joint>
    <link name="${name}_finger4_link4">
      <inertial>
        <origin xyz="0.016401338086554 -0.000465187190866685 2.14248312181697E-06" rpy="0 0 0"/>
        <mass value="0.0041380545037449"/>
        <inertia ixx="1.20869219589552E-07" ixy="4.29725372551645E-08" ixz="8.81359189278016E-10" iyy="3.17049521027891E-07" iyz="-4.4280151214266E-10" izz="2.55560236671059E-07"/>
      </inertial>
      <visual>
        <origin xyz="0 0 0" rpy="0 0 0"/>
        <geometry>
          <mesh filename="package://galbot_one_charlie_description/meshes/galbot_hand2/left_finger4_link4.stl"/>
        </geometry>
        <material name="">
          <color rgba="1 1 1 1"/>
        </material>
      </visual>
      <collision>
        <origin xyz="0 0 0" rpy="0 0 0"/>
        <geometry>
          <mesh filename="package://galbot_one_charlie_description/meshes/galbot_hand2/left_finger4_link4.stl"/>
        </geometry>
      </collision>
    </link>
    <joint name="${name}_finger4_joint4" type="revolute">
      <origin xyz="0.0265 0 0" rpy="0 0 0"/>
      <parent link="${name}_finger4_link3"/>
      <child link="${name}_finger4_link4"/>
      <axis xyz="0 0 1"/>
      <limit lower="0" upper="${0.857*1.021*J2_LIMIT}" effort="10" velocity="1.5"/>
      <!-- <mimic joint="${name}_finger4_joint3" multiplier="0.857" offset="0"/> -->
    </joint>
    <link name="${name}_finger4_end_effector_link"/>
    <joint name="${name}_finger4_end_effector_joint" type="fixed">
      <origin xyz="0.0216106269287837 0.00636376159979139 0" rpy="0 0 -0.12217304763799"/>
      <parent link="${name}_finger4_link4"/>
      <child link="${name}_finger4_end_effector_link"/>
      <axis xyz="0 0 0"/>
    </joint>
    <link name="${name}_finger5_link1">
      <inertial>
        <origin xyz="0.00382575221148435 -5.0052013852997E-09 -0.00379970728509157" rpy="0 0 0"/>
        <mass value="0.000889473582525137"/>
        <inertia ixx="4.0055788387694E-08" ixy="-1.56454747077866E-14" ixz="-4.38944911232402E-09" iyy="4.42763145564234E-08" iyz="-1.56506551217156E-14" izz="1.19540185771033E-08"/>
      </inertial>
      <visual>
        <origin xyz="0 0 0" rpy="0 0 0"/>
        <geometry>
          <mesh filename="package://galbot_one_charlie_description/meshes/galbot_hand2/left_finger5_link1.stl"/>
        </geometry>
        <material name="">
          <color rgba="1 1 1 1"/>
        </material>
      </visual>
      <collision>
        <origin xyz="0 0 0" rpy="0 0 0"/>
        <geometry>
          <mesh filename="package://galbot_one_charlie_description/meshes/galbot_hand2/left_finger5_link1.stl"/>
        </geometry>
      </collision>
    </link>
    <joint name="${name}_finger5_joint1" type="revolute">
      <origin xyz="0.1283 0.0339 -0.00109315386890014" rpy="3.14159265358979 0 0"/>
      <parent link="${name}_base_link"/>
      <child link="${name}_finger5_link1"/>
      <axis xyz="0 0 1"/>
      <limit lower="-0.34906585" upper="0.34906585" effort="10" velocity="1.5"/>
    </joint>
    <link name="${name}_finger5_link2">
      <inertial>
        <origin xyz="0.0199166121070694 0.00452784516743028 -0.000303877808472977" rpy="0 0 0"/>
        <mass value="0.00346834967811122"/>
        <inertia ixx="7.47882545674794E-08" ixy="-6.37999082906374E-08" ixz="-8.29444375306924E-09" iyy="6.28681619362609E-07" iyz="-4.51118940783156E-10" izz="6.89244310692069E-07"/>
      </inertial>
      <visual>
        <origin xyz="0 0 0" rpy="0 0 0"/>
        <geometry>
          <mesh filename="package://galbot_one_charlie_description/meshes/galbot_hand2/left_finger5_link2.stl"/>
        </geometry>
        <material name="">
          <color rgba="1 1 1 1"/>
        </material>
      </visual>
      <collision>
        <origin xyz="0 0 0" rpy="0 0 0"/>
        <geometry>
          <mesh filename="package://galbot_one_charlie_description/meshes/galbot_hand2/left_finger5_link2.stl"/>
        </geometry>
      </collision>
    </link>
    <joint name="${name}_finger5_joint2" type="revolute">
      <origin xyz="0.00510000000000001 0 0.00439999999999954" rpy="1.5707963267949 0 0"/>
      <parent link="${name}_finger5_link1"/>
      <child link="${name}_finger5_link2"/>
      <axis xyz="0 0 1"/>
      <limit lower="0" upper="${J2_LIMIT}" effort="10" velocity="1.5"/>
    </joint>
    <link name="${name}_finger5_link3">
      <inertial>
        <origin xyz="0.0131841948791408 0.000998392629336242 -4.43775828881596E-05" rpy="0 0 0"/>
        <mass value="0.00240330669142529"/>
        <inertia ixx="9.21336766793996E-08" ixy="-6.73938389627189E-09" ixz="9.17491834587282E-09" iyy="2.61350743499041E-07" iyz="3.14135392902401E-09" izz="2.21858731660144E-07"/>
      </inertial>
      <visual>
        <origin xyz="0 0 0" rpy="0 0 0"/>
        <geometry>
          <mesh filename="package://galbot_one_charlie_description/meshes/galbot_hand2/left_finger5_link3.stl"/>
        </geometry>
        <material name="">
          <color rgba="1 1 1 1"/>
        </material>
      </visual>
      <collision>
        <origin xyz="0 0 0" rpy="0 0 0"/>
        <geometry>
          <mesh filename="package://galbot_one_charlie_description/meshes/galbot_hand2/left_finger5_link3.stl"/>
        </geometry>
      </collision>
    </link>
    <joint name="${name}_finger5_joint3" type="revolute">
      <origin xyz="0.0376999618833714 0.00571036952345732 0" rpy="0 0 0"/>
      <parent link="${name}_finger5_link2"/>
      <child link="${name}_finger5_link3"/>
      <axis xyz="0 0 1"/>
      <limit lower="0" upper="${1.021*J2_LIMIT}" effort="10" velocity="1.5"/>
      <!-- <mimic joint="${name}_finger5_joint2" multiplier="1.021" offset="0"/> -->
    </joint>
    <link name="${name}_finger5_link4">
      <inertial>
        <origin xyz="0.0164013380865539 -0.000465187190866682 2.14248312121329E-06" rpy="0 0 0"/>
        <mass value="0.00413805450374486"/>
        <inertia ixx="1.20869219589534E-07" ixy="4.29725372551636E-08" ixz="8.81359189277391E-10" iyy="3.1704952102789E-07" iyz="-4.42801512142424E-10" izz="2.55560236671042E-07"/>
      </inertial>
      <visual>
        <origin xyz="0 0 0" rpy="0 0 0"/>
        <geometry>
          <mesh filename="package://galbot_one_charlie_description/meshes/galbot_hand2/left_finger5_link4.stl"/>
        </geometry>
        <material name="">
          <color rgba="1 1 1 1"/>
        </material>
      </visual>
      <collision>
        <origin xyz="0 0 0" rpy="0 0 0"/>
        <geometry>
          <mesh filename="package://galbot_one_charlie_description/meshes/galbot_hand2/left_finger5_link4.stl"/>
        </geometry>
      </collision>
    </link>
    <joint name="${name}_finger5_joint4" type="revolute">
      <origin xyz="0.0265 0 0" rpy="0 0 0"/>
      <parent link="${name}_finger5_link3"/>
      <child link="${name}_finger5_link4"/>
      <axis xyz="0 0 1"/>
      <limit lower="0" upper="${0.857*1.021*J2_LIMIT}" effort="10" velocity="1.5"/>
      <!-- <mimic joint="${name}_finger5_joint3" multiplier="0.857" offset="0"/> -->
    </joint>
    <link name="${name}_finger5_end_effector_link"/>
    <joint name="${name}_finger5_end_effector_joint" type="fixed">
      <origin xyz="0.0216106269287822 0.00636376159977905 0" rpy="0 0 -0.12217304763799"/>
      <parent link="${name}_finger5_link4"/>
      <child link="${name}_finger5_end_effector_link"/>
      <axis xyz="0 0 0"/>
    </joint>
    
  </xacro:macro>
</robot>