<?xml version="1.0"?>


<robot xmlns:xacro="http://ros.org/wiki/xacro" name="robotiq_gripper">

  <xacro:macro name="right_robotiq_gripper" params="parent *origin name:=right">
    <xacro:property name="M_PI" value="3.1415926535897931" />


    <link name="${name}_flange_link">
      <inertial>
        <origin xyz="0.052829 -0.00096484 0.013285"
          rpy="1.650554875324381 -1.4578045460766436 -0.09456730554175619" />
        <mass value="0.25733" />
        <inertia ixx="0.000253668" iyy="0.000217077" izz="5.38384e-05" ixy="0" ixz="0" iyz="0" />
      </inertial>
    </link>
    <joint type="fixed" name="${name}_arm_link72${name}_flange_link_fixed">
      <parent link="${name}_arm_link7" />
      <child link="${name}_flange_link" />
      <origin xyz="0.0 0.0 0.0" rpy="1.5707963267948966 0.0 0.0" />
    </joint>
    <link name="${name}_gripper_base">
      <inertial>
        <origin xyz="0.0 -2.70394e-05 0.0354675" rpy="0 0.0 0.0" />
        <mass value="0.1" />
        <inertia ixx="0.000260285" iyy="0.000225381" izz="0.000152708" ixy="0" ixz="0" iyz="0" />
      </inertial>
      <visual name="${name}_gripper_base">
        <origin xyz="-7.771157386868508e-05 -8.42712702351449e-05 0.04196562728594845"
          rpy="-0.013358983455554974 -0.002736396273018915 -1.5641918793709912" />
        <geometry>
          <mesh
            filename="package://galbot_one_charlie_description/meshes/gripper/robotiq_gripper/gripper_base.stl" />
        </geometry>

      </visual>
      <visual name="${name}_gripper_base_coupling">
        <origin xyz="0.00011319246465425928 -0.0004415163401904986 0.005789429487108993"
          rpy="1.7072889601050028 1.5682106218492549 1.779603868216785" />
        <geometry>
          <mesh
            filename="package://galbot_one_charlie_description/meshes/gripper/robotiq_gripper/gripper_base_coupling.stl" />
        </geometry>

      </visual>
      <visual name="${name}_gripper_c_a01_85_open">
        <origin xyz="-1.260740658399933e-11 2.0181819314966533e-11 0.09737302543032982"
          rpy="-3.1415824650304747 -1.5707963267948966 0.0" />
        <geometry>
          <mesh
            filename="package://galbot_one_charlie_description/meshes/gripper/robotiq_gripper/gripper_c_a01_85_open.stl" />
        </geometry>

      </visual>
    </link>
    <joint type="fixed" name="${name}_flange_link2${name}_gripper_base_fixed">
      <parent link="${name}_flange_link" />
      <child link="${name}_gripper_base" />
      <origin xyz="-0.091 0.0 0.0" rpy="0.0 -1.5707963267948963 0.0" />
    </joint>
    <link name="${name}_gripper_left_driver">
      <inertial>
        <origin xyz="0.0 0.0177547 0.00107314" rpy="1.6425151722801996 0.0 0.0" />
        <mass value="0.00899563" />
        <inertia ixx="1.72352e-06" iyy="1.60906e-06" izz="3.22006e-07" ixy="0" ixz="0" iyz="0" />
      </inertial>
      <visual name="${name}_gripper_driver">
        <origin xyz="-0.01752973723458131 0.0016530760397943309 -0.0046962531290229035"
          rpy="-1.5711733118216724 -0.0005289542398279057 -1.6888147258559254" />
        <geometry>
          <mesh
            filename="package://galbot_one_charlie_description/meshes/gripper/robotiq_gripper/gripper_driver.stl" />
        </geometry>

      </visual>
    </link>
    <link name="${name}_robotiq_left_joint_0_jointbody">
      <inertial>
        <origin xyz="0.0 0.0 0.0" rpy="0.0 0.0 0.0" />
        <mass value="0.001" />
        <inertia ixx="1e-09" iyy="1e-09" izz="1e-09" ixy="0" ixz="0" iyz="0" />
      </inertial>
    </link>
    <joint type="revolute" name="${name}_robotiq_left_joint_0">
      <parent link="${name}_gripper_base" />
      <child link="${name}_robotiq_left_joint_0_jointbody" />
      <origin xyz="-0.0306011 0.00475 0.0657045" rpy="-1.5707963267948957 0.0 0.0" />
      <axis xyz="0.0 0.0 1.0" />
      <limit lower="0.0" upper="0.9" effort="100" velocity="100" />
    </joint>
    <joint type="fixed" name="${name}_robotiq_left_joint_0_offset">
      <parent link="${name}_robotiq_left_joint_0_jointbody" />
      <child link="${name}_gripper_left_driver" />
      <origin xyz="-0.0 -0.0 -0.0" rpy="0.0 0.0 0.0" />
    </joint>
    <link name="${name}_gripper_left_coupler">
      <inertial>
        <origin xyz="0.0 0.00301209 0.0232175" rpy="0.0 0.12903854724165864 1.5707963267948966" />
        <mass value="0.0140974" />
        <inertia ixx="4.16206e-06" iyy="3.52216e-06" izz="8.88131e-07" ixy="0" ixz="0" iyz="0" />
      </inertial>
      <visual name="${name}_gripper_coupler">
        <origin xyz="0.003677466276248348 0.019859996972667264 0.0055000029692652795"
          rpy="-1.5707963267948966 0.0 -0.25322171734362564" />
        <geometry>
          <mesh
            filename="package://galbot_one_charlie_description/meshes/gripper/robotiq_gripper/gripper_coupler.stl" />
        </geometry>

      </visual>
    </link>
    <joint type="fixed" name="${name}_gripper_left_driver2${name}_gripper_left_coupler_fixed">
      <parent link="${name}_gripper_left_driver" />
      <child link="${name}_gripper_left_coupler" />
      <origin xyz="-0.0314249 0.00453223 -0.0102" rpy="0.0 0.0 3.141592653589793" />
    </joint>
    <link name="${name}_gripper_left_spring_link">
      <inertial>
        <origin xyz="-8.65005e-09 0.0181624 0.0212658"
          rpy="0.0 0.7068443151232264 1.5707963267948966" />
        <mass value="0.0221642" />
        <inertia ixx="8.96853e-06" iyy="6.71733e-06" izz="2.63931e-06" ixy="0" ixz="0" iyz="0" />
      </inertial>
      <visual name="${name}_gripper_spring_link">
        <origin xyz="-0.01829995209475023 -0.020573191085122067 0.012049995218164638"
          rpy="1.5707963267948966 0.0 -0.7266945071344781" />
        <geometry>
          <mesh
            filename="package://galbot_one_charlie_description/meshes/gripper/robotiq_gripper/gripper_spring_link.stl" />
        </geometry>

      </visual>
    </link>
    <link name="${name}_robotiq_left_joint_1_jointbody">
      <inertial>
        <origin xyz="0.0 0.0 0.0" rpy="0.0 0.0 0.0" />
        <mass value="0.001" />
        <inertia ixx="1e-09" iyy="1e-09" izz="1e-09" ixy="0" ixz="0" iyz="0" />
      </inertial>
    </link>
    <joint type="revolute" name="${name}_robotiq_left_joint_1">
      <parent link="${name}_gripper_base" />
      <child link="${name}_robotiq_left_joint_1_jointbody" />
      <origin xyz="-0.0127 -0.012 0.07222" rpy="-1.5707963267948957 0.0 0.0" />
      <axis xyz="0.0 0.0 1.0" />
      <limit lower="-0.29670597283" upper="0.9" effort="100" velocity="100" />
    </joint>
    <joint type="fixed" name="${name}_robotiq_left_joint_1_offset">
      <parent link="${name}_robotiq_left_joint_1_jointbody" />
      <child link="${name}_gripper_left_spring_link" />
      <origin xyz="-0.0 -0.0 -0.0" rpy="0.0 0.0 0.0" />
    </joint>
    <link name="${name}_gripper_left_follower">
      <inertial>
        <origin xyz="0.0 -0.011046 0.0124786" rpy="0.32977841348127324 0.0 0.0" />
        <mass value="0.0125222" />
        <inertia ixx="2.67415e-06" iyy="2.4559e-06" izz="6.02031e-07" ixy="0" ixz="0" iyz="0" />
      </inertial>
      <visual name="${name}_gripper_follower">
        <origin xyz="-0.0038737521886743204 0.018163543281937117 -0.009073555180291397"
          rpy="-0.7344036602895134 1.569545402060931 0.6100596314850433" />
        <geometry>
          <mesh
            filename="package://galbot_one_charlie_description/meshes/gripper/robotiq_gripper/gripper_follower.stl" />
        </geometry>

      </visual>
      <visual name="${name}_gripper_follower_c">
        <origin xyz="-0.004699980164726128 0.02141275113631695 -0.009147873055216952"
          rpy="-1.5119778521084566 1.5530009459127831 -0.14325231278215655" />
        <geometry>
          <mesh
            filename="package://galbot_one_charlie_description/meshes/gripper/robotiq_gripper/gripper_follower_c.stl" />
        </geometry>

      </visual>
    </link>
    <link name="${name}_robotiq_left_joint_2_jointbody">
      <inertial>
        <origin xyz="0.0 0.0 0.0" rpy="0.0 0.0 0.0" />
        <mass value="0.001" />
        <inertia ixx="1e-09" iyy="1e-09" izz="1e-09" ixy="0" ixz="0" iyz="0" />
      </inertial>
    </link>
    <joint type="revolute" name="${name}_robotiq_left_joint_2">
      <parent link="${name}_gripper_left_spring_link" />
      <child link="${name}_robotiq_left_joint_2_jointbody" />
      <origin xyz="-0.0382079 -0.0425003 0.00295" rpy="3.141592653589793 0.0 0.0" />
      <axis xyz="0.0 0.0 1.0" />
      <limit lower="-0.872664" upper="0.9" effort="100" velocity="100" />
    </joint>
    <joint type="fixed" name="${name}_robotiq_left_joint_2_offset">
      <parent link="${name}_robotiq_left_joint_2_jointbody" />
      <child link="${name}_gripper_left_follower" />
      <origin xyz="-0.0 -0.0 -0.0" rpy="0.0 0.0 0.0" />
    </joint>
    <link name="${name}_gripper_right_driver">
      <inertial>
        <origin xyz="2.96931e-12 0.0177547 0.00107314" rpy="1.6425151722801996 0.0 0.0" />
        <mass value="0.00899563" />
        <inertia ixx="1.72352e-06" iyy="1.60906e-06" izz="3.22006e-07" ixy="0" ixz="0" iyz="0" />
      </inertial>
      <visual name="${name}_gripper_driver">
        <origin xyz="-0.01752973723458131 0.0016530760397943309 -0.0046962531290229035"
          rpy="-1.5711733118216724 -0.0005289542398279057 -1.6888147258559254" />
        <geometry>
          <mesh
            filename="package://galbot_one_charlie_description/meshes/gripper/robotiq_gripper/gripper_driver.stl" />
        </geometry>

      </visual>
    </link>
    <link name="${name}_robotiq_right_joint_0_jointbody">
      <inertial>
        <origin xyz="0.0 0.0 0.0" rpy="0.0 0.0 0.0" />
        <mass value="0.001" />
        <inertia ixx="1e-09" iyy="1e-09" izz="1e-09" ixy="0" ixz="0" iyz="0" />
      </inertial>
    </link>
    <joint type="revolute" name="${name}_robotiq_right_joint_0">
      <parent link="${name}_gripper_base" />
      <child link="${name}_robotiq_right_joint_0_jointbody" />
      <origin xyz="0.0306011 -0.00475 0.0657045" rpy="-1.5707963267948963 0.0 -3.141592653589793" />
      <axis xyz="0.0 0.0 1.0" />
      <limit lower="0.0" upper="0.9" effort="100" velocity="100" />
    </joint>
    <joint type="fixed" name="${name}_robotiq_right_joint_0_offset">
      <parent link="${name}_robotiq_right_joint_0_jointbody" />
      <child link="${name}_gripper_right_driver" />
      <origin xyz="-0.0 -0.0 -0.0" rpy="0.0 0.0 0.0" />
    </joint>
    <link name="${name}_gripper_right_coupler">
      <inertial>
        <origin xyz="0.0 0.00301209 0.0232175" rpy="0.0 0.12903854724165864 1.5707963267948966" />
        <mass value="0.0140974" />
        <inertia ixx="4.16206e-06" iyy="3.52216e-06" izz="8.88131e-07" ixy="0" ixz="0" iyz="0" />
      </inertial>
      <visual name="${name}_gripper_coupler">
        <origin xyz="0.003677466276248348 0.019859996972667264 0.0055000029692652795"
          rpy="-1.5707963267948966 0.0 -0.25322171734362564" />
        <geometry>
          <mesh
            filename="package://galbot_one_charlie_description/meshes/gripper/robotiq_gripper/gripper_coupler.stl" />
        </geometry>

      </visual>
    </link>
    <joint type="fixed" name="${name}_gripper_right_driver2${name}_gripper_right_coupler_fixed">
      <parent link="${name}_gripper_right_driver" />
      <child link="${name}_gripper_right_coupler" />
      <origin xyz="-0.0314249 0.00453223 -0.0102" rpy="0.0 0.0 3.141592653589793" />
    </joint>
    <link name="${name}_gripper_right_spring_link">
      <inertial>
        <origin xyz="-8.65005e-09 0.0181624 0.0212658"
          rpy="0.0 0.7068443151232264 1.5707963267948966" />
        <mass value="0.0221642" />
        <inertia ixx="8.96853e-06" iyy="6.71733e-06" izz="2.63931e-06" ixy="0" ixz="0" iyz="0" />
      </inertial>
      <visual name="${name}_gripper_spring_link">
        <origin xyz="-0.01829995209475023 -0.020573191085122067 0.012049995218164638"
          rpy="1.5707963267948966 0.0 -0.7266945071344781" />
        <geometry>
          <mesh
            filename="package://galbot_one_charlie_description/meshes/gripper/robotiq_gripper/gripper_spring_link.stl" />
        </geometry>

      </visual>
    </link>
    <link name="${name}_robotiq_right_joint_1_jointbody">
      <inertial>
        <origin xyz="0.0 0.0 0.0" rpy="0.0 0.0 0.0" />
        <mass value="0.001" />
        <inertia ixx="1e-09" iyy="1e-09" izz="1e-09" ixy="0" ixz="0" iyz="0" />
      </inertial>
    </link>
    <joint type="revolute" name="${name}_robotiq_right_joint_1">
      <parent link="${name}_gripper_base" />
      <child link="${name}_robotiq_right_joint_1_jointbody" />
      <origin xyz="0.0127 0.012 0.07222" rpy="-1.5707963267948963 0.0 -3.141592653589793" />
      <axis xyz="0.0 0.0 1.0" />
      <limit lower="-0.29670597283" upper="0.9" effort="100" velocity="100" />
    </joint>
    <joint type="fixed" name="${name}_robotiq_right_joint_1_offset">
      <parent link="${name}_robotiq_right_joint_1_jointbody" />
      <child link="${name}_gripper_right_spring_link" />
      <origin xyz="-0.0 -0.0 -0.0" rpy="0.0 0.0 0.0" />
    </joint>
    <link name="${name}_gripper_right_follower">
      <inertial>
        <origin xyz="0.0 -0.011046 0.0124786" rpy="0.32977841348127324 0.0 0.0" />
        <mass value="0.0125222" />
        <inertia ixx="2.67415e-06" iyy="2.4559e-06" izz="6.02031e-07" ixy="0" ixz="0" iyz="0" />
      </inertial>
      <visual name="${name}_gripper_follower">
        <origin xyz="-0.0038737521886743204 0.018163543281937117 -0.009073555180291397"
          rpy="-0.7344036602895134 1.569545402060931 0.6100596314850433" />
        <geometry>
          <mesh
            filename="package://galbot_one_charlie_description/meshes/gripper/robotiq_gripper/gripper_follower.stl" />
        </geometry>

      </visual>
      <visual name="${name}_gripper_follower_c">
        <origin xyz="-0.004699980164726128 0.02141275113631695 -0.009147873055216952"
          rpy="-1.5119778521084566 1.5530009459127831 -0.14325231278215655" />
        <geometry>
          <mesh
            filename="package://galbot_one_charlie_description/meshes/gripper/robotiq_gripper/gripper_follower_c.stl" />
        </geometry>

      </visual>
    </link>
    <link name="${name}_robotiq_right_joint_2_jointbody">
      <inertial>
        <origin xyz="0.0 0.0 0.0" rpy="0.0 0.0 0.0" />
        <mass value="0.001" />
        <inertia ixx="1e-09" iyy="1e-09" izz="1e-09" ixy="0" ixz="0" iyz="0" />
      </inertial>
    </link>
    <joint type="revolute" name="${name}_robotiq_right_joint_2">
      <parent link="${name}_gripper_right_spring_link" />
      <child link="${name}_robotiq_right_joint_2_jointbody" />
      <origin xyz="-0.0382079 -0.0425003 0.00295" rpy="3.141592653589793 0.0 0.0" />
      <axis xyz="0.0 0.0 1.0" />
      <limit lower="-0.872664" upper="0.9" effort="100" velocity="100" />
    </joint>
    <joint type="fixed" name="${name}_robotiq_right_joint_2_offset">
      <parent link="${name}_robotiq_right_joint_2_jointbody" />
      <child link="${name}_gripper_right_follower" />
      <origin xyz="-0.0 -0.0 -0.0" rpy="0.0 0.0 0.0" />
    </joint>

    <!-- Tool Center Point -->
    <link name="${name}_gripper_tcp_link" />
    <joint name="${name}_gripper_tcp_joint" type="fixed">
      <origin xyz="0.172892 0 0 " rpy="1.5707963267948966 0 0" />
      <parent link="${name}_arm_end_effector_mount_link" />
      <child link="${name}_gripper_tcp_link" />
      <axis xyz="0 0 0" />
    </joint>

  </xacro:macro>
</robot>