<?xml version='1.0' encoding='UTF-8'?>
<!-- 
#####################################################################################
#
# Copyright (c) 2023-2025 Galbot, Inc. All Rights Reserved.
#
# This software contains confidential and proprietary information of Galbot, Inc.
# ("Confidential Information"). You shall not disclose such Confidential Information
# and shall use it only in accordance with the terms of the license agreement you
# entered into with Galbot, Inc.
#
# UNAUTHORIZED COPYING, USE, OR DISTRIBUTION OF THIS SOFTWARE, OR ANY PORTION OR
# DERIVATIVE THEREOF, IS STRICTLY PROHIBITED. IF YOU HAVE RECEIVED THIS SOFTWARE IN
# ERROR, PLEASE NOTIFY GALBOT, INC. IMMEDIATELY AND DELETE IT FROM YOUR SYSTEM.
#
#####################################################################################
#
# Description: Xacro file for Galbot One Charlie head.
# Author: Herman Ye@Galbot, Yuhao Zeng@Galbot
#
#####################################################################################
-->
<robot xmlns:xacro="http://ros.org/wiki/xacro" name="head">
    <xacro:macro name="head" params="parent *origin name:=head">
        <xacro:property name="M_PI" value="3.1415926535897931" />

        <joint name="${name}_joint" type="fixed">
            <xacro:insert_block name="origin" />
            <parent link="${parent}" />
            <child link="${name}_base_link" />
        </joint>

        <link name="${name}_base_link">
            <inertial>
                <origin xyz="0 0 0" rpy="0 0 0" />
                <mass value="0" />
                <inertia ixx="0" ixy="0" ixz="0" iyy="0" iyz="0" izz="0" />
            </inertial>
        </link>

        <link name="${name}_link1">
            <inertial>
                <origin rpy="0 0 0" xyz="0.00000 0.00004 -0.04238" />
                <mass value="0.41" />
                <inertia ixx="0.00110" ixy="-0.00000" ixz="0.00000" iyy="0.00113" iyz="0.00008"
                    izz="0.00014" />
            </inertial>
        </link>
        <joint name="${name}_joint1" type="revolute">
            <origin xyz="0 0 0" rpy="0 0 0" />
            <parent link="${name}_base_link" />
            <child link="${name}_link1" />
            <axis xyz="0 0 1" />
            <limit lower="-1.570796327" upper="1.570796327" effort="4" velocity="1.5" />

        </joint>
        <link name="${name}_link2">
            <inertial>
                <origin rpy="0 0 0" xyz="0.03200 -0.03753 0.00162" />
                <mass value="0.75" />
                <inertia ixx="0.00380" ixy="-0.00070" ixz="0.00000" iyy="0.00367" iyz="-0.00000"
                    izz="0.00538" />
            </inertial>
            <visual>
                <origin xyz="0 0 0" rpy="0 0 0" />
                <geometry>
                    <mesh
                        filename="package://galbot_one_charlie_description/meshes/head/head_link2.obj" />
                </geometry>

            </visual>
            <collision>
                <origin xyz="0 0 0" rpy="0 0 0" />
                <geometry>
                    <mesh
                        filename="package://galbot_one_charlie_description/meshes/head/head_link2.stl" />
                </geometry>
            </collision>

        </link>
        <joint name="${name}_joint2" type="revolute">
            <origin xyz="0 0 0" rpy="${-M_PI/2} 0 0" />
            <parent link="${name}_link1" />
            <child link="${name}_link2" />
            <axis xyz="0 0 1" />
            <limit lower="-0.366519143" upper="0.366519143" effort="4" velocity="1.5" />
        </joint>

        <link name="${name}_end_effector_mount_link">
            <inertial>
                <origin xyz="0 0 0" rpy="0 0 0" />
                <mass value="0" />
                <inertia ixx="0" ixy="0" ixz="0" iyy="0" iyz="0" izz="0" />
            </inertial>
        </link>
        <joint name="${name}_end_effector_mount_joint" type="fixed">
            <origin xyz="0 0 0" rpy="0 0 0" />
            <parent link="${name}_link2" />
            <child link="${name}_end_effector_mount_link" />
            <axis xyz="0 0 0" />
        </joint>

    </xacro:macro>
</robot>