<?xml version='1.0' encoding='UTF-8'?>
<!-- 
#####################################################################################
#
# Copyright (c) 2023-2025 Galbot, Inc. All Rights Reserved.
#
# This software contains confidential and proprietary information of Galbot, Inc.
# ("Confidential Information"). You shall not disclose such Confidential Information
# and shall use it only in accordance with the terms of the license agreement you
# entered into with Galbot, Inc.
#
# UNAUTHORIZED COPYING, USE, OR DISTRIBUTION OF THIS SOFTWARE, OR ANY PORTION OR
# DERIVATIVE THEREOF, IS STRICTLY PROHIBITED. IF YOU HAVE RECEIVED THIS SOFTWARE IN
# ERROR, PLEASE NOTIFY GALBOT, INC. IMMEDIATELY AND DELETE IT FROM YOUR SYSTEM.
#
#####################################################################################
#
# Description: Xacro file for Galbot One Charlie right hand.
# Author: Herman Ye@Galbot, Yuhao Zeng@Galbot
#
#####################################################################################
-->
<robot xmlns:xacro="http://www.ros.org/wiki/xacro" name="galbot_right_hand">
  <xacro:macro name="inertial_matrix" params="mass">
    <inertial>
      <mass value="${mass}"/>
      <inertia ixx="1.0" ixy="0.0" ixz="0.0" iyy="0.5" iyz="0.0" izz="1.0"/>
    </inertial>
  </xacro:macro>
  <xacro:macro name="Box_inertial_matrix" params="m l w h">
    <inertial>
      <mass value="${m}"/>
      <inertia ixx="${m*(h*h + l*l)/12}" ixy="0" ixz="0" iyy="${m*(w*w + l*l)/12}" iyz="0" izz="${m*(w*w + h*h)/12}"/>
    </inertial>
  </xacro:macro>

  <xacro:macro name="galbot_right_hand" params="parent *origin name:=galbot_hand">
    <xacro:property name="M_PI" value="3.1415926535897931"/>

    <joint name="${name}_joint" type="fixed">
      <xacro:insert_block name="origin"/>
      <parent link="${parent}"/>
      <child link="${name}_base_link"/>
    </joint>
    <link name="${name}_base_link">
      <inertial>
        <origin xyz="0.0082419 0.068841 0.00013637" rpy="0 0 0"/>
        <mass value="0.25036"/>
        <inertia ixx="0.00045101" ixy="4.3512E-06" ixz="5.459E-07" iyy="0.00028657" iyz="-5.703E-06" izz="0.00021919"/>
      </inertial>
      <visual>
        <origin xyz="0 0 0" rpy="0 0 0"/>
        <geometry>
          <mesh filename="package://galbot_one_charlie_description/meshes/galbot_hand/base_link_right.stl"/>
        </geometry>
        <material name="">
          <color rgba="0.75294 0.75294 0.75294 1"/>
        </material>
      </visual>
      <collision>
        <origin xyz="0 0 0" rpy="0 0 0"/>
        <geometry>
          <mesh filename="package://galbot_one_charlie_description/meshes/galbot_hand/base_link_right.stl"/>
        </geometry>
      </collision>
    </link>
    <link name="${name}_finger1_link1">
      <inertial>
        <origin xyz="0.004995 8.7149E-06 4.5429E-11" rpy="0 0 0"/>
        <mass value="0.00049419"/>
        <inertia ixx="5.3424E-09" ixy="1.1328E-14" ixz="6.9289E-16" iyy="1.3374E-08" iyz="-8.1629E-16" izz="1.5765E-08"/>
      </inertial>
      <visual>
        <origin xyz="0 0 0" rpy="0 0 0"/>
        <geometry>
          <mesh filename="package://galbot_one_charlie_description/meshes/galbot_hand/right_finger1_link1.stl"/>
        </geometry>
        <material name="">
          <color rgba="0.89804 0.90588 0.91765 1"/>
        </material>
      </visual>
      <collision>
        <origin xyz="0 0 0" rpy="0 0 0"/>
        <geometry>
          <mesh filename="package://galbot_one_charlie_description/meshes/galbot_hand/right_finger1_link1.stl"/>
        </geometry>
      </collision>
    </link>
    <joint name="${name}_finger1_joint1" type="revolute">
      <origin xyz="-0.03285 0.069 0.01381" rpy="-1.5708 -0.43633 -3.1416"/>
      <parent link="${name}_base_link"/>
      <child link="${name}_finger1_link1"/>
      <axis xyz="0 0 1"/>
      <limit lower="-0.436333" upper="0.436333" effort="10" velocity="1.5"/>
    </joint>
    <link name="${name}_finger1_link2">
      <inertial>
        <origin xyz="-0.0197638113646088 0.0119884351204036 -6.47583720675415E-08" rpy="0 0 0"/>
        <mass value="0.0104414084749297"/>
        <inertia ixx="2.26938971460816E-06" ixy="6.95671895082844E-07" ixz="5.17563439827828E-12" iyy="1.95674475637677E-06" iyz="-1.8146676089102E-11" izz="2.64036940238189E-06"/>
      </inertial>
      <visual>
        <origin xyz="0 0 0" rpy="0 0 0"/>
        <geometry>
          <mesh filename="package://galbot_one_charlie_description/meshes/galbot_hand/right_finger1_link2.stl"/>
        </geometry>
        <material name="">
          <color rgba="0.898039215686275 0.905882352941176 0.917647058823529 1"/>
        </material>
      </visual>
      <collision>
        <origin xyz="0 0 0" rpy="0 0 0"/>
        <geometry>
          <mesh filename="package://galbot_one_charlie_description/meshes/galbot_hand/right_finger1_link2.stl"/>
        </geometry>
      </collision>
    </link>
    <joint name="${name}_finger1_joint2" type="revolute">
      <origin xyz="0.011996 0 0" rpy="-1.5708 0.86998 -3.1416"/>
      <parent link="${name}_finger1_link1"/>
      <child link="${name}_finger1_link2"/>
      <axis xyz="0 0 -1"/>
      <limit lower="0" upper="1.50551734" effort="10" velocity="1.5"/>
    </joint>
    <link name="${name}_finger1_link3">
      <inertial>
        <origin xyz="0.0120682555874391 0.0157241622001568 -1.02067244663051E-07" rpy="0 0 0"/>
        <mass value="0.0076968888894129"/>
        <inertia ixx="1.1726091868184E-06" ixy="-4.07923072902364E-07" ixz="-5.24185280531264E-12" iyy="8.88278793376918E-07" iyz="6.13497236919717E-12" izz="1.48324986772178E-06"/>
      </inertial>
      <visual>
        <origin xyz="0 0 0" rpy="0 0 0"/>
        <geometry>
          <mesh filename="package://galbot_one_charlie_description/meshes/galbot_hand/right_finger1_link3.stl"/>
        </geometry>
        <material name="">
          <color rgba="0.898039215686275 0.905882352941176 0.917647058823529 1"/>
        </material>
      </visual>
      <collision>
        <origin xyz="0 0 0" rpy="0 0 0"/>
        <geometry>
          <mesh filename="package://galbot_one_charlie_description/meshes/galbot_hand/right_finger1_link3.stl"/>
        </geometry>
      </collision>
    </link>
    <joint name="${name}_finger1_joint3" type="revolute">
      <origin xyz="-0.03095 0.030567 0" rpy="-3.1416 0 -3.0848"/>
      <parent link="${name}_finger1_link2"/>
      <child link="${name}_finger1_link3"/>
      <axis xyz="0 0 1"/>
      <limit lower="0" upper="1.23805297" effort="10" velocity="1.5"/>
    </joint>
    <link name="${name}_finger1_link4">
      <inertial>
        <origin xyz="0.0137393508215277 0.00523874565059427 1.47490922253191E-10" rpy="0 0 0"/>
        <mass value="0.00601167993964778"/>
        <inertia ixx="3.64167528790483E-07" ixy="9.03019810969208E-08" ixz="6.29210447472367E-12" iyy="6.52661994490432E-07" iyz="-3.46109520069899E-12" izz="5.53534912148834E-07"/>
      </inertial>
      <visual>
        <origin xyz="0 0 0" rpy="0 0 0"/>
        <geometry>
          <mesh filename="package://galbot_one_charlie_description/meshes/galbot_hand/right_finger1_link4.stl"/>
        </geometry>
        <material name="">
          <color rgba="0.898039215686275 0.905882352941176 0.917647058823529 1"/>
        </material>
      </visual>
      <collision>
        <origin xyz="0 0 0" rpy="0 0 0"/>
        <geometry>
          <mesh filename="package://galbot_one_charlie_description/meshes/galbot_hand/right_finger1_link4.stl"/>
        </geometry>
      </collision>
    </link>
    <joint name="${name}_finger1_joint4" type="revolute">
      <origin xyz="0.024254 0.030534 0" rpy="0 0 0.82545"/>
      <parent link="${name}_finger1_link3"/>
      <child link="${name}_finger1_link4"/>
      <axis xyz="0 0 1"/>
      <limit lower="0" upper="1.07637884" effort="10" velocity="1.5"/>
    </joint>
    <link name="${name}_finger1_end_effector_link">
    </link>
    <joint name="${name}_finger1_end_effector_joint" type="fixed">
      <origin xyz="0.021345 0.006117 0" rpy="0 0 0"/>
      <parent link="${name}_finger1_link4"/>
      <child link="${name}_finger1_end_effector_link"/>
      <axis xyz="0 0 0"/>
    </joint>
    <link name="${name}_finger2_link1">
      <inertial>
        <origin xyz="0.00499906779370619 2.5219036303703E-09 -7.00310144943761E-10" rpy="0 0 0"/>
        <mass value="0.000494192567929614"/>
        <inertia ixx="5.3423985521446E-09" ixy="3.90839790222105E-15" ixz="-1.22441161173858E-15" iyy="1.33735101332351E-08" iyz="-1.15373303038692E-16" izz="1.57645319003349E-08"/>
      </inertial>
      <visual>
        <origin xyz="0 0 0" rpy="0 0 0"/>
        <geometry>
          <mesh filename="package://galbot_one_charlie_description/meshes/galbot_hand/right_finger2_link1.stl"/>
        </geometry>
        <material name="">
          <color rgba="0.898039215686275 0.905882352941176 0.917647058823529 1"/>
        </material>
      </visual>
      <collision>
        <origin xyz="0 0 0" rpy="0 0 0"/>
        <geometry>
          <mesh filename="package://galbot_one_charlie_description/meshes/galbot_hand/right_finger2_link1.stl"/>
        </geometry>
      </collision>
    </link>
    <joint name="${name}_finger2_joint1" type="revolute">
      <origin xyz="-0.02385 0.142 0.0338" rpy="1.5708 0 1.5708"/>
      <parent link="${name}_base_link"/>
      <child link="${name}_finger2_link1"/>
      <axis xyz="0 0 1"/>
      <limit lower="-0.436333" upper="0.436333" effort="10" velocity="1.5"/>
    </joint>
    <link name="${name}_finger2_link2">
      <inertial>
        <origin xyz="-0.0186381023362613 0.0107405395766148 6.64738062650105E-08" rpy="0 0 0"/>
        <mass value="0.0111711924506811"/>
        <inertia ixx="2.33104107461343E-06" ixy="6.93393463927505E-07" ixz="-4.90461334694945E-13" iyy="1.95500143647408E-06" iyz="7.77559373929327E-12" izz="2.63422452401262E-06"/>
      </inertial>
      <visual>
        <origin xyz="0 0 0" rpy="0 0 0"/>
        <geometry>
          <mesh filename="package://galbot_one_charlie_description/meshes/galbot_hand/right_finger2_link2.stl"/>
        </geometry>
        <material name="">
          <color rgba="1 1 1 1"/>
        </material>
      </visual>
      <collision>
        <origin xyz="0 0 0" rpy="0 0 0"/>
        <geometry>
          <mesh filename="package://galbot_one_charlie_description/meshes/galbot_hand/right_finger2_link2.stl"/>
        </geometry>
      </collision>
    </link>
    <joint name="${name}_finger2_joint2" type="revolute">
      <origin xyz="0.012 0 0" rpy="-1.5708 0.86998 -3.1416"/>
      <parent link="${name}_finger2_link1"/>
      <child link="${name}_finger2_link2"/>
      <axis xyz="0 0 -1"/>
      <limit lower="0" upper="1.45958033" effort="10" velocity="1.5"/>
    </joint>
    <link name="${name}_finger2_link3">
      <inertial>
        <origin xyz="0.00934475037345902 0.0128197232965583 1.59461179816134E-08" rpy="0 0 0"/>
        <mass value="0.00617814830189644"/>
        <inertia ixx="7.5787317806045E-07" ixy="-2.62117034401506E-07" ixz="9.53124838087193E-13" iyy="6.81948958018871E-07" iyz="-9.09691463190549E-13" izz="1.02516471185422E-06"/>
      </inertial>
      <visual>
        <origin xyz="0 0 0" rpy="0 0 0"/>
        <geometry>
          <mesh filename="package://galbot_one_charlie_description/meshes/galbot_hand/right_finger2_link3.stl"/>
        </geometry>
        <material name="">
          <color rgba="0.898039215686275 0.905882352941176 0.917647058823529 1"/>
        </material>
      </visual>
      <collision>
        <origin xyz="0 0 0" rpy="0 0 0"/>
        <geometry>
          <mesh filename="package://galbot_one_charlie_description/meshes/galbot_hand/right_finger2_link3.stl"/>
        </geometry>
      </collision>
    </link>
    <joint name="${name}_finger2_joint3" type="revolute">
      <origin xyz="-0.029716 0.029398 0" rpy="3.1416 0 -3.0848"/>
      <parent link="${name}_finger2_link2"/>
      <child link="${name}_finger2_link3"/>
      <axis xyz="0 0 1"/>
      <limit lower="0" upper="1.42521995" effort="10" velocity="1.5"/>
    </joint>
    <link name="${name}_finger2_link4">
      <inertial>
        <origin xyz="0.0135273213448935 0.00576298251975127 3.83376195373097E-08" rpy="0 0 0"/>
        <mass value="0.00601173996414688"/>
        <inertia ixx="3.57653695977892E-07" ixy="7.89550155623852E-08" ixz="2.61262934762474E-11" iyy="6.59158954124062E-07" iyz="1.69010425734659E-11" izz="5.5351301755672E-07"/>
      </inertial>
      <visual>
        <origin xyz="0 0 0" rpy="0 0 0"/>
        <geometry>
          <mesh filename="package://galbot_one_charlie_description/meshes/galbot_hand/right_finger2_link4.stl"/>
        </geometry>
        <material name="">
          <color rgba="0.898039215686275 0.905882352941176 0.917647058823529 1"/>
        </material>
      </visual>
      <collision>
        <origin xyz="0 0 0" rpy="0 0 0"/>
        <geometry>
          <mesh filename="package://galbot_one_charlie_description/meshes/galbot_hand/right_finger2_link4.stl"/>
        </geometry>
      </collision>
    </link>
    <joint name="${name}_finger2_joint4" type="revolute">
      <origin xyz="0.02113 0.025978 0" rpy="0 0 0.82545"/>
      <parent link="${name}_finger2_link3"/>
      <child link="${name}_finger2_link4"/>
      <axis xyz="0 0 1"/>
      <limit lower="0" upper="1.33165452" effort="10" velocity="1.5"/>
    </joint>
    <link name="${name}_finger2_end_effector_link">
    </link>
    <joint name="${name}_finger2_end_effector_joint" type="fixed">
      <origin xyz="0.021094 0.0069335 0" rpy="0 0 0"/>
      <parent link="${name}_finger2_link4"/>
      <child link="${name}_finger2_end_effector_link"/>
      <axis xyz="0 0 0"/>
    </joint>
    <link name="${name}_finger3_link1">
      <inertial>
        <origin xyz="0.00499906779370636 2.52190364424809E-09 -4.84088828051066E-10" rpy="0 0 0"/>
        <mass value="0.000494192567929613"/>
        <inertia ixx="5.34239855214459E-09" ixy="3.90839791102644E-15" ixz="-1.22441158178898E-15" iyy="1.33735101332351E-08" iyz="-1.30668855776301E-16" izz="1.57645319003348E-08"/>
      </inertial>
      <visual>
        <origin xyz="0 0 0" rpy="0 0 0"/>
        <geometry>
          <mesh filename="package://galbot_one_charlie_description/meshes/galbot_hand/right_finger3_link1.stl"/>
        </geometry>
        <material name="">
          <color rgba="0.898039215686275 0.905882352941176 0.917647058823529 1"/>
        </material>
      </visual>
      <collision>
        <origin xyz="0 0 0" rpy="0 0 0"/>
        <geometry>
          <mesh filename="package://galbot_one_charlie_description/meshes/galbot_hand/right_finger3_link1.stl"/>
        </geometry>
      </collision>
    </link>
    <joint name="${name}_finger3_joint1" type="revolute">
      <origin xyz="-0.02385 0.142 0" rpy="1.5708 0 1.5708"/>
      <parent link="${name}_base_link"/>
      <child link="${name}_finger3_link1"/>
      <axis xyz="0 0 1"/>
      <limit lower="-0.436333" upper="0.436333" effort="10" velocity="1.5"/>
    </joint>
    <link name="${name}_finger3_link2">
      <inertial>
        <origin xyz="-0.0186381022533214 0.0107405395416611 6.64936977007313E-08" rpy="0 0 0"/>
        <mass value="0.0111711924112354"/>
        <inertia ixx="2.33104106570944E-06" ixy="6.93393454784971E-07" ixz="-4.87179070675973E-13" iyy="1.95500142193922E-06" iyz="7.77328100470882E-12" izz="2.6342245047578E-06"/>
      </inertial>
      <visual>
        <origin xyz="0 0 0" rpy="0 0 0"/>
        <geometry>
          <mesh filename="package://galbot_one_charlie_description/meshes/galbot_hand/right_finger3_link2.stl"/>
        </geometry>
        <material name="">
          <color rgba="1 1 1 1"/>
        </material>
      </visual>
      <collision>
        <origin xyz="0 0 0" rpy="0 0 0"/>
        <geometry>
          <mesh filename="package://galbot_one_charlie_description/meshes/galbot_hand/right_finger3_link2.stl"/>
        </geometry>
      </collision>
    </link>
    <joint name="${name}_finger3_joint2" type="revolute">
      <origin xyz="0.012 0 0" rpy="-1.5708 0.86998 3.1416"/>
      <parent link="${name}_finger3_link1"/>
      <child link="${name}_finger3_link2"/>
      <axis xyz="0 0 -1"/>
      <limit lower="0" upper="1.45958033" effort="10" velocity="1.5"/>
    </joint>
    <link name="${name}_finger3_link3">
      <inertial>
        <origin xyz="0.00934475050211912 0.0128197229918609 1.56828517672292E-08" rpy="0 0 0"/>
        <mass value="0.00617814852272355"/>
        <inertia ixx="7.57873218145058E-07" ixy="-2.6211703055126E-07" ixz="9.55815251850356E-13" iyy="6.81948971045792E-07" iyz="-9.28567749822938E-13" izz="1.02516474015376E-06"/>
      </inertial>
      <visual>
        <origin xyz="0 0 0" rpy="0 0 0"/>
        <geometry>
          <mesh filename="package://galbot_one_charlie_description/meshes/galbot_hand/right_finger3_link3.stl"/>
        </geometry>
        <material name="">
          <color rgba="0.898039215686275 0.905882352941176 0.917647058823529 1"/>
        </material>
      </visual>
      <collision>
        <origin xyz="0 0 0" rpy="0 0 0"/>
        <geometry>
          <mesh filename="package://galbot_one_charlie_description/meshes/galbot_hand/right_finger3_link3.stl"/>
        </geometry>
      </collision>
    </link>
    <joint name="${name}_finger3_joint3" type="revolute">
      <origin xyz="-0.029716 0.029398 0" rpy="3.1416 0 -3.0848"/>
      <parent link="${name}_finger3_link2"/>
      <child link="${name}_finger3_link3"/>
      <axis xyz="0 0 1"/>
      <limit lower="0" upper="1.42521995" effort="10" velocity="1.5"/>
    </joint>
    <link name="${name}_finger3_link4">
      <inertial>
        <origin xyz="0.0135273213448937 0.00576298251975123 3.83376195928209E-08" rpy="0 0 0"/>
        <mass value="0.00601173996414699"/>
        <inertia ixx="3.57653695977897E-07" ixy="7.89550155623841E-08" ixz="2.61262934701131E-11" iyy="6.5915895412408E-07" iyz="1.69010425719313E-11" izz="5.53513017556735E-07"/>
      </inertial>
      <visual>
        <origin xyz="0 0 0" rpy="0 0 0"/>
        <geometry>
          <mesh filename="package://galbot_one_charlie_description/meshes/galbot_hand/right_finger3_link4.stl"/>
        </geometry>
        <material name="">
          <color rgba="0.898039215686275 0.905882352941176 0.917647058823529 1"/>
        </material>
      </visual>
      <collision>
        <origin xyz="0 0 0" rpy="0 0 0"/>
        <geometry>
          <mesh filename="package://galbot_one_charlie_description/meshes/galbot_hand/right_finger3_link4.stl"/>
        </geometry>
      </collision>
    </link>
    <joint name="${name}_finger3_joint4" type="revolute">
      <origin xyz="0.02113 0.025978 0" rpy="0 0 0.82545"/>
      <parent link="${name}_finger3_link3"/>
      <child link="${name}_finger3_link4"/>
      <axis xyz="0 0 1"/>
      <limit lower="0" upper="1.33165452" effort="10" velocity="1.5"/>
    </joint>
    <link name="${name}_finger3_end_effector_link">
    </link>
    <joint name="${name}_finger3_end_effector_joint" type="fixed">
      <origin xyz="0.021094 0.0069335 0" rpy="0 0 0"/>
      <parent link="${name}_finger3_link4"/>
      <child link="${name}_finger3_end_effector_link"/>
      <axis xyz="0 0 0"/>
    </joint>
    <link name="${name}_finger4_link1">
      <inertial>
        <origin xyz="0.00499906779370652 2.52190364037596E-09 -2.67867525036158E-10" rpy="0 0 0"/>
        <mass value="0.000494192567929613"/>
        <inertia ixx="5.34239855214459E-09" ixy="3.90839790739408E-15" ixz="-1.22441158556461E-15" iyy="1.33735101332351E-08" iyz="-1.3066885578012E-16" izz="1.57645319003349E-08"/>
      </inertial>
      <visual>
        <origin xyz="0 0 0" rpy="0 0 0"/>
        <geometry>
          <mesh filename="package://galbot_one_charlie_description/meshes/galbot_hand/right_finger4_link1.stl"/>
        </geometry>
        <material name="">
          <color rgba="0.898039215686275 0.905882352941176 0.917647058823529 1"/>
        </material>
      </visual>
      <collision>
        <origin xyz="0 0 0" rpy="0 0 0"/>
        <geometry>
          <mesh filename="package://galbot_one_charlie_description/meshes/galbot_hand/right_finger4_link1.stl"/>
        </geometry>
      </collision>
    </link>
    <joint name="${name}_finger4_joint1" type="revolute">
      <origin xyz="-0.02385 0.142 -0.0338" rpy="1.5708 0 1.5708"/>
      <parent link="${name}_base_link"/>
      <child link="${name}_finger4_link1"/>
      <axis xyz="0 0 1"/>
      <limit lower="-0.436333" upper="0.436333" effort="10" velocity="1.5"/>
    </joint>
    <link name="${name}_finger4_link2">
      <inertial>
        <origin xyz="-0.0186381023945565 0.0107405396320499 6.65026438790444E-08" rpy="0 0 0"/>
        <mass value="0.0111711925002666"/>
        <inertia ixx="2.33104108365488E-06" ixy="6.93393473554513E-07" ixz="-4.84880935846891E-13" iyy="1.95500145355396E-06" iyz="7.77151003070869E-12" izz="2.63422454490073E-06"/>
      </inertial>
      <visual>
        <origin xyz="0 0 0" rpy="0 0 0"/>
        <geometry>
          <mesh filename="package://galbot_one_charlie_description/meshes/galbot_hand/right_finger4_link2.stl"/>
        </geometry>
        <material name="">
          <color rgba="1 1 1 1"/>
        </material>
      </visual>
      <collision>
        <origin xyz="0 0 0" rpy="0 0 0"/>
        <geometry>
          <mesh filename="package://galbot_one_charlie_description/meshes/galbot_hand/right_finger4_link2.stl"/>
        </geometry>
      </collision>
    </link>
    <joint name="${name}_finger4_joint2" type="revolute">
      <origin xyz="0.012 0 0" rpy="-1.5708 0.86998 3.1416"/>
      <parent link="${name}_finger4_link1"/>
      <child link="${name}_finger4_link2"/>
      <axis xyz="0 0 -1"/>
      <limit lower="0" upper="1.45958033" effort="10" velocity="1.5"/>
    </joint>
    <link name="${name}_finger4_link3">
      <inertial>
        <origin xyz="0.00934475055570621 0.0128197228855712 1.56005088472244E-08" rpy="0 0 0"/>
        <mass value="0.0061781485921843"/>
        <inertia ixx="7.57873231944316E-07" ixy="-2.62117028420887E-07" ixz="9.57458681628821E-13" iyy="6.81948975016763E-07" iyz="-9.35106111107108E-13" izz="1.02516475055295E-06"/>
      </inertial>
      <visual>
        <origin xyz="0 0 0" rpy="0 0 0"/>
        <geometry>
          <mesh filename="package://galbot_one_charlie_description/meshes/galbot_hand/right_finger4_link3.stl"/>
        </geometry>
        <material name="">
          <color rgba="0.898039215686275 0.905882352941176 0.917647058823529 1"/>
        </material>
      </visual>
      <collision>
        <origin xyz="0 0 0" rpy="0 0 0"/>
        <geometry>
          <mesh filename="package://galbot_one_charlie_description/meshes/galbot_hand/right_finger4_link3.stl"/>
        </geometry>
      </collision>
    </link>
    <joint name="${name}_finger4_joint3" type="revolute">
      <origin xyz="-0.029716 0.029398 0" rpy="3.1416 0 -3.0848"/>
      <parent link="${name}_finger4_link2"/>
      <child link="${name}_finger4_link3"/>
      <axis xyz="0 0 1"/>
      <limit lower="0" upper="1.42521995" effort="10" velocity="1.5"/>
    </joint>
    <link name="${name}_finger4_link4">
      <inertial>
        <origin xyz="0.0135273160506967 0.00576299030052829 3.29077335614241E-08" rpy="0 0 0"/>
        <mass value="0.00601173271035026"/>
        <inertia ixx="3.57653416751521E-07" ixy="7.89548294632823E-08" ixz="2.63407714013318E-11" iyy="6.59158506333225E-07" iyz="1.67605116711692E-11" izz="5.53512603794628E-07"/>
      </inertial>
      <visual>
        <origin xyz="0 0 0" rpy="0 0 0"/>
        <geometry>
          <mesh filename="package://galbot_one_charlie_description/meshes/galbot_hand/right_finger4_link4.stl"/>
        </geometry>
        <material name="">
          <color rgba="0.898039215686275 0.905882352941176 0.917647058823529 1"/>
        </material>
      </visual>
      <collision>
        <origin xyz="0 0 0" rpy="0 0 0"/>
        <geometry>
          <mesh filename="package://galbot_one_charlie_description/meshes/galbot_hand/right_finger4_link4.stl"/>
        </geometry>
      </collision>
    </link>
    <joint name="${name}_finger4_joint4" type="revolute">
      <origin xyz="0.02113 0.025978 0" rpy="0 0 0.82545"/>
      <parent link="${name}_finger4_link3"/>
      <child link="${name}_finger4_link4"/>
      <axis xyz="0 0 1"/>
      <limit lower="0" upper="1.33165452" effort="10" velocity="1.5"/>
    </joint>
    <link name="${name}_finger4_end_effector_link">
    </link>
    <joint name="${name}_finger4_end_effector_joint" type="fixed">
      <origin xyz="0.021094 0.0069335 0" rpy="0 0 0"/>
      <parent link="${name}_finger4_link4"/>
      <child link="${name}_finger4_end_effector_link"/>
      <axis xyz="0 0 0"/>
    </joint>
  </xacro:macro>
</robot>