<?xml version='1.0' encoding='UTF-8'?>
<!-- 
#####################################################################################
#
# Copyright (c) 2023-2025 Galbot, Inc. All Rights Reserved.
#
# This software contains confidential and proprietary information of Galbot, Inc.
# ("Confidential Information"). You shall not disclose such Confidential Information
# and shall use it only in accordance with the terms of the license agreement you
# entered into with Galbot, Inc.
#
# UNAUTHORIZED COPYING, USE, OR DISTRIBUTION OF THIS SOFTWARE, OR ANY PORTION OR
# DERIVATIVE THEREOF, IS STRICTLY PROHIBITED. IF YOU HAVE RECEIVED THIS SOFTWARE IN
# ERROR, PLEASE NOTIFY GALBOT, INC. IMMEDIATELY AND DELETE IT FROM YOUR SYSTEM.
#
#####################################################################################
#
# Description: Xacro file for Galbot One Charlie left hand.
# Author: Herman Ye@Galbot, Yuhao Zeng@Galbot
#
#####################################################################################
-->
<robot xmlns:xacro="http://www.ros.org/wiki/xacro" name="galbot_left_hand">
  <xacro:macro name="inertial_matrix" params="mass">
    <inertial>
      <mass value="${mass}"/>
      <inertia ixx="1.0" ixy="0.0" ixz="0.0" iyy="0.5" iyz="0.0" izz="1.0"/>
    </inertial>
  </xacro:macro>
  <xacro:macro name="Box_inertial_matrix" params="m l w h">
    <inertial>
      <mass value="${m}"/>
      <inertia ixx="${m*(h*h + l*l)/12}" ixy="0" ixz="0" iyy="${m*(w*w + l*l)/12}" iyz="0" izz="${m*(w*w + h*h)/12}"/>
    </inertial>
  </xacro:macro>
  <xacro:macro name="galbot_left_hand" params="parent *origin name:=galbot_hand">
    <xacro:property name="M_PI" value="3.1415926535897931"/>

    <joint name="${name}_joint" type="fixed">
      <xacro:insert_block name="origin"/>
      <parent link="${parent}"/>
      <child link="${name}_base_link"/>
    </joint>
    <link name="${name}_base_link">
      <inertial>
        <origin xyz="0.0082426499546434 0.0688400826362062 0.00066904058606776" rpy="0 0 0"/>
        <mass value="0.250361410722848"/>
        <inertia ixx="0.000451009774708177" ixy="4.34532396591773E-06" ixz="9.13519050609304E-07" iyy="0.00028655291942187" iyz="6.75652280731711E-06" izz="0.000219205453464452"/>
      </inertial>
      <visual>
        <origin xyz="0 0 0" rpy="0 0 0"/>
        <geometry>
          <mesh
            filename="package://galbot_one_charlie_description/meshes/galbot_hand/base_link_left.stl"/>
        </geometry>
        <material name="">
          <color rgba="0.752941176470588 0.752941176470588 0.752941176470588 1"/>
        </material>
      </visual>
      <collision>
        <origin xyz="0 0 0" rpy="0 0 0"/>
        <geometry>
          <mesh
            filename="package://galbot_one_charlie_description/meshes/galbot_hand/base_link_left.stl"/>
        </geometry>
      </collision>
    </link>
    <link name="${name}_finger1_link1">
      <inertial>
        <origin xyz="0.0049990479204143 8.87043942465748E-09 1.56826572561553E-10" rpy="0 0 0"/>
        <mass value="0.000494193898584918"/>
        <inertia ixx="5.34240304366998E-09" ixy="1.40165523546363E-14" ixz="1.58814446596312E-16" iyy="1.3373535733049E-08" iyz="-8.36240707742665E-16" izz="1.57645609851102E-08"/>
      </inertial>
      <visual>
        <origin xyz="0 0 0" rpy="0 0 0"/>
        <geometry>
          <mesh
            filename="package://galbot_one_charlie_description/meshes/galbot_hand/left_finger1_link1.stl"/>
        </geometry>
        <material name="">
          <color rgba="0.898039215686275 0.909803921568627 0.92156862745098 1"/>
        </material>
      </visual>
      <collision>
        <origin xyz="0 0 0" rpy="0 0 0"/>
        <geometry>
          <mesh
            filename="package://galbot_one_charlie_description/meshes/galbot_hand/left_finger1_link1.stl"/>
        </geometry>
      </collision>
    </link>
    <joint name="${name}_finger1_joint1" type="revolute">
      <origin xyz="-0.03285 0.069 -0.0138" rpy="-1.5708 0.43633 -3.1416"/>
      <parent link="${name}_base_link"/>
      <child link="${name}_finger1_link1"/>
      <axis xyz="0 0 1"/>
      <limit lower="-0.436333" upper="0.436333" effort="10" velocity="1.5"/>
    </joint>
    <link name="${name}_finger1_link2">
      <inertial>
        <origin xyz="-0.019763814098464 0.0119884370804753 -6.74106527299989E-08" rpy="0 0 0"/>
         <mass value="0.0104414043171337"/>
        <inertia ixx="2.26938802597705E-06" ixy="6.95671474272708E-07" ixz="4.84261342651834E-12" iyy="1.95674472909177E-06" iyz="-1.63443414489251E-11" izz="2.6403675046715E-06"/>
      </inertial>
      <visual>
         <origin xyz="0 0 0" rpy="0 0 0"/>
        <geometry>
          <mesh
            filename="package://galbot_one_charlie_description/meshes/galbot_hand/left_finger1_link2.stl"/>
        </geometry>
        <material name="">
          <color rgba="0.898039215686275 0.909803921568627 0.92156862745098 1"/>
        </material>
      </visual>
      <collision>
         <origin xyz="0 0 0" rpy="0 0 0"/>
        <geometry>
          <mesh
            filename="package://galbot_one_charlie_description/meshes/galbot_hand/left_finger1_link2.stl"/>
        </geometry>
      </collision>
    </link>
    <joint name="${name}_finger1_joint2" type="revolute">
      <origin xyz="0.012 0 0" rpy="-1.5708 0.86998 -3.1416"/>
      <parent link="${name}_finger1_link1"/>
      <child link="${name}_finger1_link2"/>
      <axis xyz="0 0 -1"/>
      <limit lower="0" upper="1.50551734" effort="10" velocity="1.5"/>
    </joint>
    <link name="${name}_finger1_link3">
      <inertial>
         <origin xyz="0.0120682639015778 0.015724151161845 -9.74408693628359E-08" rpy="0 0 0"/>
         <mass value="0.00769687851220105"/>
        <inertia ixx="1.17260853356787E-06" ixy="-4.07923446815966E-07" ixz="-5.33297576143919E-12" iyy="8.88278129831767E-07" iyz="6.47568421551231E-12" izz="1.48324891392563E-06"/>
      </inertial>
      <visual>
         <origin xyz="0 0 0" rpy="0 0 0"/>
        <geometry>
          <mesh
            filename="package://galbot_one_charlie_description/meshes/galbot_hand/left_finger1_link3.stl"/>
        </geometry>
        <material name="">
          <color rgba="0.898039215686275 0.909803921568627 0.92156862745098 1"/>
        </material>
      </visual>
      <collision>
         <origin xyz="0 0 0" rpy="0 0 0"/>
        <geometry>
          <mesh
            filename="package://galbot_one_charlie_description/meshes/galbot_hand/left_finger1_link3.stl"/>
        </geometry>
      </collision>
    </link>
    <joint name="${name}_finger1_joint3" type="revolute">
      <origin xyz="-0.03095 0.030567 0" rpy="-3.1416 0 -3.0848"/>
      <parent link="${name}_finger1_link2"/>
      <child link="${name}_finger1_link3"/>
      <axis xyz="0 0 1"/>
      <limit lower="0" upper="1.23805297" effort="10" velocity="1.5"/>
    </joint>
    <link name="${name}_finger1_link4">
      <inertial>
         <origin xyz="0.0137391542777864 0.0052384549865301 6.8093028111893E-08" rpy="0 0 0"/>
         <mass value="0.00601170990282722"/>
        <inertia ixx="3.64164120565208E-07" ixy="9.03182223249479E-08" ixz="4.11160375971961E-11" iyy="6.52648406186183E-07" iyz="2.64088107653073E-11" izz="5.53508591348595E-07"/>
      </inertial>
      <visual>
         <origin xyz="0 0 0" rpy="0 0 0"/>
        <geometry>
          <mesh
            filename="package://galbot_one_charlie_description/meshes/galbot_hand/left_finger1_link4.stl"/>
        </geometry>
        <material name="">
          <color rgba="0.898039215686275 0.909803921568627 0.92156862745098 1"/>
        </material>
      </visual>
      <collision>
         <origin xyz="0 0 0" rpy="0 0 0"/>
        <geometry>
          <mesh
            filename="package://galbot_one_charlie_description/meshes/galbot_hand/left_finger1_link4.stl"/>
        </geometry>
      </collision>
    </link>
    <joint name="${name}_finger1_joint4" type="revolute">
      <origin xyz="0.024254 0.030534 0" rpy="0 0 0.82545"/>
      <parent link="${name}_finger1_link3"/>
      <child link="${name}_finger1_link4"/>
      <axis xyz="0 0 1"/>
      <limit lower="0" upper="1.07637884" effort="10" velocity="1.5"/>
    </joint>
    <link name="${name}_finger1_end_effector_link" />
    <joint name="${name}_finger1_end_effector_joint" type="fixed">
      <origin xyz="0.021345 0.006117 0" rpy="0 0 0"/>
      <parent link="${name}_finger1_link4"/>
      <child link="${name}_finger1_end_effector_link"/>
      <axis xyz="0 0 1"/>
    </joint>
    <link name="${name}_finger2_link1">
      <inertial>
         <origin xyz="0.00499905936590745 3.68050198868996E-09 -7.00310150147931E-10" rpy="0 0 0"/>
         <mass value="0.000494192567929613"/>
        <inertia ixx="5.34239855214459E-09" ixy="3.90839790058759E-15" ixz="-1.22441161075751E-15" iyy="1.33735101332351E-08" iyz="-1.15373298356861E-16" izz="1.57645319003349E-08"/>
      </inertial>
      <visual>
         <origin xyz="0 0 0" rpy="0 0 0"/>
        <geometry>
          <mesh
            filename="package://galbot_one_charlie_description/meshes/galbot_hand/left_finger2_link1.stl"/>
        </geometry>
        <material name="">
          <color rgba="0.898039215686275 0.909803921568627 0.92156862745098 1"/>
        </material>
      </visual>
      <collision>
         <origin xyz="0 0 0" rpy="0 0 0"/>
        <geometry>
          <mesh
            filename="package://galbot_one_charlie_description/meshes/galbot_hand/left_finger2_link1.stl"/>
        </geometry>
      </collision>
    </link>
    <joint name="${name}_finger2_joint1" type="revolute">
      <origin xyz="-0.02385 0.142 -0.0338" rpy="1.5708 0 1.5708"/>
      <parent link="${name}_base_link"/>
      <child link="${name}_finger2_link1"/>
      <axis xyz="0 0 1"/>
      <limit lower="-0.436333" upper="0.436333" effort="10" velocity="1.5"/>
    </joint>
    <link name="${name}_finger2_link2">
      <inertial>
         <origin xyz="-0.0185286193226101 0.0108010517820986 8.01215642255507E-08" rpy="0 0 0"/>
         <mass value="0.0111711822126339"/>
        <inertia ixx="2.33104017787741E-06" ixy="6.93393208834101E-07" ixz="-1.44493245066058E-12" iyy="1.95499944751113E-06" iyz="7.98730979349519E-12" izz="2.63422330573402E-06"/>
      </inertial>
      <visual>
         <origin xyz="0 0 0" rpy="0 0 0"/>
        <geometry>
          <mesh
            filename="package://galbot_one_charlie_description/meshes/galbot_hand/left_finger2_link2.stl"/>
        </geometry>
        <material name="">
          <color rgba="1 1 1 1"/>
        </material>
      </visual>
      <collision>
         <origin xyz="0 0 0" rpy="0 0 0"/>
        <geometry>
          <mesh
            filename="package://galbot_one_charlie_description/meshes/galbot_hand/left_finger2_link2.stl"/>
        </geometry>
      </collision>
    </link>
    <joint name="${name}_finger2_joint2" type="revolute">
      <origin xyz="0.012 0 0" rpy="-1.5708 0.86998 -3.1416"/>
      <parent link="${name}_finger2_link1"/>
      <child link="${name}_finger2_link2"/>
      <axis xyz="0 0 -1"/>
      <limit lower="0" upper="1.45958033" effort="10" velocity="1.5"/>
    </joint>
    <link name="${name}_finger2_link3">
      <inertial>
         <origin xyz="0.00913593443840779 0.0129569323748436 1.56005088376998E-08" rpy="0 0 0"/>
         <mass value="0.00617814859218431"/>
        <inertia ixx="7.57873231944315E-07" ixy="-2.62117028420887E-07" ixz="9.57458681916455E-13" iyy="6.81948975016763E-07" iyz="-9.35106110683383E-13" izz="1.02516475055295E-06"/>
      </inertial>
      <visual>
         <origin xyz="0 0 0" rpy="0 0 0"/>
        <geometry>
          <mesh
            filename="package://galbot_one_charlie_description/meshes/galbot_hand/left_finger2_link3.stl"/>
        </geometry>
        <material name="">
          <color rgba="0.898039215686275 0.909803921568627 0.92156862745098 1"/>
        </material>
      </visual>
      <collision>
         <origin xyz="0 0 0" rpy="0 0 0"/>
        <geometry>
          <mesh
            filename="package://galbot_one_charlie_description/meshes/galbot_hand/left_finger2_link3.stl"/>
        </geometry>
      </collision>
    </link>
    <joint name="${name}_finger2_joint3" type="revolute">
      <origin xyz="-0.029716 0.029398 0" rpy="-3.1416 0 -3.0848"/>
      <parent link="${name}_finger2_link2"/>
      <child link="${name}_finger2_link3"/>
      <axis xyz="0 0 1"/>
      <limit lower="0" upper="1.42521995" effort="10" velocity="1.5"/>
    </joint>
    <link name="${name}_finger2_link4">
      <inertial>
         <origin xyz="0.0125505752127241 0.00560132755653497 3.29077335703356E-08" rpy="0 0 0"/>
         <mass value="0.00601173271035027"/>
        <inertia ixx="3.57653416751526E-07" ixy="7.8954829463275E-08" ixz="2.63407713962598E-11" iyy="6.59158506333203E-07" iyz="1.6760511676366E-11" izz="5.53512603794612E-07"/>
      </inertial>
      <visual>
         <origin xyz="0 0 0" rpy="0 0 0"/>
        <geometry>
          <mesh
            filename="package://galbot_one_charlie_description/meshes/galbot_hand/left_finger2_link4.stl"/>
        </geometry>
        <material name="">
          <color rgba="0.898039215686275 0.909803921568627 0.92156862745098 1"/>
        </material>
      </visual>
      <collision>
         <origin xyz="0 0 0" rpy="0 0 0"/>
        <geometry>
          <mesh
            filename="package://galbot_one_charlie_description/meshes/galbot_hand/left_finger2_link4.stl"/>
        </geometry>
      </collision>
    </link>
    <joint name="${name}_finger2_joint4" type="revolute">
      <origin xyz="0.02113 0.025978 0" rpy="0 0 0.82545"/>
      <parent link="${name}_finger2_link3"/>
      <child link="${name}_finger2_link4"/>
      <axis xyz="0 0 1"/>
      <limit lower="0" upper="1.33165452" effort="10" velocity="1.5"/>
    </joint>
    <link name="${name}_finger2_end_effector_link" />
    <joint name="${name}_finger2_end_effector_joint" type="fixed">
      <origin xyz="0.021094 0.0069335 0" rpy="0 0 0"/>
      <parent link="${name}_finger2_link4"/>
      <child link="${name}_finger2_end_effector_link"/>
      <axis xyz="0 0 1"/>
    </joint>
    <link name="${name}_finger3_link1">
      <inertial>
         <origin xyz="0.00499905936590745 3.68050199345271E-09 -7.00310146678484E-10" rpy="0 0 0"/>
         <mass value="0.000494192567929613"/>
        <inertia ixx="5.34239855214459E-09" ixy="3.90839790635189E-15" ixz="-1.22441161105375E-15" iyy="1.33735101332351E-08" iyz="-1.1537329821269E-16" izz="1.57645319003348E-08"/>
      </inertial>
      <visual>
         <origin xyz="0 0 0" rpy="0 0 0"/>
        <geometry>
          <mesh
            filename="package://galbot_one_charlie_description/meshes/galbot_hand/left_finger3_link1.stl"/>
        </geometry>
        <material name="">
          <color rgba="0.898039215686275 0.909803921568627 0.92156862745098 1"/>
        </material>
      </visual>
      <collision>
         <origin xyz="0 0 0" rpy="0 0 0"/>
        <geometry>
          <mesh
            filename="package://galbot_one_charlie_description/meshes/galbot_hand/left_finger3_link1.stl"/>
        </geometry>
      </collision>
    </link>
    <joint name="${name}_finger3_joint1" type="revolute">
      <origin xyz="-0.02385 0.142 0" rpy="1.5708 0 1.5708"/>
      <parent link="${name}_base_link"/>
      <child link="${name}_finger3_link1"/>
      <axis xyz="0 0 1"/>
      <limit lower="-0.436333" upper="0.436333" effort="10" velocity="1.5"/>
    </joint>
    <link name="${name}_finger3_link2">
      <inertial>
         <origin xyz="-0.0185286191813749 0.0108010516917097 8.01126181088074E-08" rpy="0 0 0"/>
         <mass value="0.0111711821236026"/>
        <inertia ixx="2.33104015993199E-06" ixy="6.93393190064569E-07" ixz="-1.44723057445807E-12" iyy="1.95499941589643E-06" iyz="7.98908075778866E-12" izz="2.63422326559113E-06"/>
      </inertial>
      <visual>
         <origin xyz="0 0 0" rpy="0 0 0"/>
        <geometry>
          <mesh
            filename="package://galbot_one_charlie_description/meshes/galbot_hand/left_finger3_link2.stl"/>
        </geometry>
        <material name="">
          <color rgba="1 1 1 1"/>
        </material>
      </visual>
      <collision>
         <origin xyz="0 0 0" rpy="0 0 0"/>
        <geometry>
          <mesh
            filename="package://galbot_one_charlie_description/meshes/galbot_hand/left_finger3_link2.stl"/>
        </geometry>
      </collision>
    </link>
    <joint name="${name}_finger3_joint2" type="revolute">
      <origin xyz="0.0119999915848734 0 0" rpy="-1.57079631687457 0.869975067859879 -3.14159265358979"/>
      <parent link="${name}_finger3_link1"/>
      <child link="${name}_finger3_link2"/>
      <axis xyz="0 0 -1"/>
      <limit lower="0" upper="1.45958033" effort="10" velocity="1.5"/>
    </joint>
    <link name="${name}_finger3_link3">
      <inertial>
         <origin xyz="0.00913593438482067 0.0129569324811332 1.56828517741681E-08" rpy="0 0 0"/>
         <mass value="0.00617814852272354"/>
        <inertia ixx="7.57873218145056E-07" ixy="-2.6211703055126E-07" ixz="9.55815252068849E-13" iyy="6.81948971045792E-07" iyz="-9.28567749181378E-13" izz="1.02516474015375E-06"/>
      </inertial>
      <visual>
         <origin xyz="0 0 0" rpy="0 0 0"/>
        <geometry>
          <mesh
            filename="package://galbot_one_charlie_description/meshes/galbot_hand/left_finger3_link3.stl"/>
        </geometry>
        <material name="">
          <color rgba="0.898039215686275 0.909803921568627 0.92156862745098 1"/>
        </material>
      </visual>
      <collision>
         <origin xyz="0 0 0" rpy="0 0 0"/>
        <geometry>
          <mesh
            filename="package://galbot_one_charlie_description/meshes/galbot_hand/left_finger3_link3.stl"/>
        </geometry>
      </collision>
    </link>
    <joint name="${name}_finger3_joint3" type="revolute">
      <origin xyz="-0.0297156396415835 0.0293976318891706 0" rpy="-3.14159264368545 0 -3.08482058368093"/>
      <parent link="${name}_finger3_link2"/>
      <child link="${name}_finger3_link3"/>
      <axis xyz="0 0 1"/>
      <limit lower="0" upper="1.42521995" effort="10" velocity="1.5"/>
    </joint>
    <link name="${name}_finger3_link4">
      <inertial>
         <origin xyz="0.012550580506921 0.00560131977575767 3.83736363310239E-08" rpy="0 0 0"/>
         <mass value="0.00601173996414697"/>
        <inertia ixx="3.57653695977901E-07" ixy="7.8955015562208E-08" ixz="2.61268011496655E-11" iyy="6.59158954123838E-07" iyz="1.69017218847581E-11" izz="5.53513017556934E-07"/>
      </inertial>
      <visual>
         <origin xyz="0 0 0" rpy="0 0 0"/>
        <geometry>
          <mesh
            filename="package://galbot_one_charlie_description/meshes/galbot_hand/left_finger3_link4.stl"/>
        </geometry>
        <material name="">
          <color rgba="0.898039215686275 0.909803921568627 0.92156862745098 1"/>
        </material>
      </visual>
      <collision>
         <origin xyz="0 0 0" rpy="0 0 0"/>
        <geometry>
          <mesh
            filename="package://galbot_one_charlie_description/meshes/galbot_hand/left_finger3_link4.stl"/>
        </geometry>
      </collision>
    </link>
    <joint name="${name}_finger3_joint4" type="revolute">
      <origin xyz="0.0211295881742376 0.0259778848944081 0" rpy="0 0 0.825449979072216"/>
      <parent link="${name}_finger3_link3"/>
      <child link="${name}_finger3_link4"/>
      <axis xyz="0 0 1"/>
      <limit lower="0" upper="1.33165452" effort="10" velocity="1.5"/>
    </joint>
    <link name="${name}_finger3_end_effector_link" />
    <joint name="${name}_finger3_end_effector_joint" type="fixed">
      <origin xyz="0.0210938445145526 0.0069334786960683 0" rpy="0 0 0"/>
      <parent link="${name}_finger3_link4"/>
      <child link="${name}_finger3_end_effector_link"/>
      <axis xyz="0 0 1"/>
    </joint>
    <link name="${name}_finger4_link1">
      <inertial>
         <origin xyz="0.00499905936590745 3.68050198651382E-09 -6.71515757930119E-10" rpy="0 0 0"/>
         <mass value="0.000494192567929614"/>
        <inertia ixx="5.34239855214462E-09" ixy="3.9083979130977E-15" ixz="-1.28444263028581E-15" iyy="1.33735101332351E-08" iyz="-1.30668837972129E-16" izz="1.57645319003348E-08"/>
      </inertial>
      <visual>
         <origin xyz="0 0 0" rpy="0 0 0"/>
        <geometry>
          <mesh
            filename="package://galbot_one_charlie_description/meshes/galbot_hand/left_finger4_link1.stl"/>
        </geometry>
        <material name="">
          <color rgba="0.898039215686275 0.909803921568627 0.92156862745098 1"/>
        </material>
      </visual>
      <collision>
         <origin xyz="0 0 0" rpy="0 0 0"/>
        <geometry>
          <mesh
            filename="package://galbot_one_charlie_description/meshes/galbot_hand/left_finger4_link1.stl"/>
        </geometry>
      </collision>
    </link>
    <joint name="${name}_finger4_joint1" type="revolute">
      <origin xyz="-0.0238500029693464 0.142000008484246 0.0337999986286747" rpy="1.5707963267949 0 1.5707963267949"/>
      <parent link="${name}_base_link"/>
      <child link="${name}_finger4_link1"/>
      <axis xyz="0 0 1"/>
      <limit lower="-0.436333" upper="0.436333" effort="10" velocity="1.5"/>
    </joint>
    <link name="${name}_finger4_link2">
      <inertial>
         <origin xyz="-0.0185286192452257 0.0108010517349734 8.01998765731504E-08" rpy="0 0 0"/>
         <mass value="0.0111711821630483"/>
        <inertia ixx="2.33104016883598E-06" ixy="6.93393199207108E-07" ixz="-1.44363415591741E-12" iyy="1.95499943043111E-06" iyz="7.98465537401374E-12" izz="2.63422328484608E-06"/>
      </inertial>
      <visual>
         <origin xyz="0 0 0" rpy="0 0 0"/>
        <geometry>
          <mesh
            filename="package://galbot_one_charlie_description/meshes/galbot_hand/left_finger4_link2.stl"/>
        </geometry>
        <material name="">
          <color rgba="1 1 1 1"/>
        </material>
      </visual>
      <collision>
         <origin xyz="0 0 0" rpy="0 0 0"/>
        <geometry>
          <mesh
            filename="package://galbot_one_charlie_description/meshes/galbot_hand/left_finger4_link2.stl"/>
        </geometry>
      </collision>
    </link>
    <joint name="${name}_finger4_joint2" type="revolute">
      <origin xyz="0.0119999915848734 0 0" rpy="-1.57079633671522 0.869975073619836 3.14159264600756"/>
      <parent link="${name}_finger4_link1"/>
      <child link="${name}_finger4_link2"/>
      <axis xyz="0 0 -1"/>
      <limit lower="0" upper="1.45958033" effort="10" velocity="1.5"/>
    </joint>
    <link name="${name}_finger4_link3">
      <inertial>
         <origin xyz="0.00913593425616056 0.0129569327858307 1.59461179954912E-08" rpy="0 0 0"/>
         <mass value="0.00617814830189644"/>
        <inertia ixx="7.57873178060449E-07" ixy="-2.62117034401506E-07" ixz="9.53124838056616E-13" iyy="6.81948958018871E-07" iyz="-9.09691463062282E-13" izz="1.02516471185422E-06"/>
      </inertial>
      <visual>
         <origin xyz="0 0 0" rpy="0 0 0"/>
        <geometry>
          <mesh
            filename="package://galbot_one_charlie_description/meshes/galbot_hand/left_finger4_link3.stl"/>
        </geometry>
        <material name="">
          <color rgba="0.898039215686275 0.909803921568627 0.92156862745098 1"/>
        </material>
      </visual>
      <collision>
         <origin xyz="0 0 0" rpy="0 0 0"/>
        <geometry>
          <mesh
            filename="package://galbot_one_charlie_description/meshes/galbot_hand/left_finger4_link3.stl"/>
        </geometry>
      </collision>
    </link>
    <joint name="${name}_finger4_joint3" type="revolute">
      <origin xyz="-0.029715639641601 0.0293976318891584 0" rpy="-3.14159265358979 0 -3.08482058368093"/>
      <parent link="${name}_finger4_link2"/>
      <child link="${name}_finger4_link3"/>
      <axis xyz="0 0 1"/>
      <limit lower="0" upper="1.42521995" effort="10" velocity="1.5"/>
    </joint>
    <link name="${name}_finger4_link4">
      <inertial>
         <origin xyz="0.0125505805069208 0.00560131977575771 3.83736362685738E-08" rpy="0 0 0"/>
         <mass value="0.00601173996414686"/>
        <inertia ixx="3.57653695977895E-07" ixy="7.89550155622099E-08" ixz="2.61268011540066E-11" iyy="6.59158954123818E-07" iyz="1.69017218871917E-11" izz="5.53513017556917E-07"/>
      </inertial>
      <visual>
         <origin xyz="0 0 0" rpy="0 0 0"/>
        <geometry>
          <mesh
            filename="package://galbot_one_charlie_description/meshes/galbot_hand/left_finger4_link4.stl"/>
        </geometry>
        <material name="">
          <color rgba="0.898039215686275 0.909803921568627 0.92156862745098 1"/>
        </material>
      </visual>
      <collision>
         <origin xyz="0 0 0" rpy="0 0 0"/>
        <geometry>
          <mesh
            filename="package://galbot_one_charlie_description/meshes/galbot_hand/left_finger4_link4.stl"/>
        </geometry>
      </collision>
    </link>
    <joint name="${name}_finger4_joint4" type="revolute">
      <origin xyz="0.0211295881742195 0.0259778848944192 0" rpy="0 0 0.825449979072216"/>
      <parent link="${name}_finger4_link3"/>
      <child link="${name}_finger4_link4"/>
      <axis xyz="0 0 1"/>
      <limit lower="0" upper="1.33165452" effort="10" velocity="1.5"/>
    </joint>
    <link name="${name}_finger4_end_effector_link" />
    <joint name="${name}_finger4_end_effector_joint" type="fixed">
      <origin xyz="0.0210938445145526 0.00693347869606831 0" rpy="0 0 0"/>
      <parent link="${name}_finger4_link4"/>
      <child link="${name}_finger4_end_effector_link"/>
      <axis xyz="0 0 1"/>
    </joint>
    </xacro:macro>
</robot>