<?xml version='1.0' encoding='UTF-8'?>
<!-- 
#####################################################################################
#
# Copyright (c) 2023-2025 Galbot, Inc. All Rights Reserved.
#
# This software contains confidential and proprietary information of Galbot, Inc.
# ("Confidential Information"). You shall not disclose such Confidential Information
# and shall use it only in accordance with the terms of the license agreement you
# entered into with Galbot, Inc.
#
# UNAUTHORIZED COPYING, USE, OR DISTRIBUTION OF THIS SOFTWARE, OR ANY PORTION OR
# DERIVATIVE THEREOF, IS STRICTLY PROHIBITED. IF YOU HAVE RECEIVED THIS SOFTWARE IN
# ERROR, PLEASE NOTIFY GALBOT, INC. IMMEDIATELY AND DELETE IT FROM YOUR SYSTEM.
#
#####################################################################################
#
# Description: Xacro file for Galbot One Charlie leg.
# Author: Herman Ye@Galbot, Yuhao Zeng@Galbot
#
#####################################################################################
-->
<robot xmlns:xacro="http://ros.org/wiki/xacro" name="leg">

  <xacro:macro name="leg" params="parent *origin name:=leg">
    <xacro:property name="M_PI" value="3.1415926535897931"/>

    <joint name="${name}_joint" type="fixed">
      <xacro:insert_block name="origin"/>
      <parent link="${parent}"/>
      <child link="${name}_base_link"/>
    </joint>

    <link name="${name}_base_link">
      <inertial>
        <origin rpy="0 0 0" xyz="0.00138 -0.01502 -0.05360"/>
        <mass value="1.98"/>
        <inertia ixx="0.01545" ixy="0.0" ixz="0.0" iyy="0.01172" iyz="0.0" izz="0.00904"/>

      </inertial>
    </link>

    <link name="${name}_link1">
      <inertial>
        <origin rpy="0 0 0" xyz="0.23126 0.00187 -0.01166"/>
        <mass value="13.38"/>
        <inertia ixx="0.05540" ixy="0.00267" ixz="-0.03511" iyy="1.17040" iyz="-0.00012" izz="1.15967"/>
      </inertial>
      <visual>
        <origin xyz="0 0 0" rpy="0 0 0"/>
        <geometry>
          <mesh filename="package://galbot_one_charlie_description/meshes/leg/leg_link1.obj"/>
        </geometry>

      </visual>
      <collision>
        <origin xyz="0 0 0" rpy="0 0 0"/>
        <geometry>
          <mesh filename="package://galbot_one_charlie_description/meshes/leg/leg_link1.stl"/>
        </geometry>
      </collision>
    </link>

    <joint name="${name}_joint1" type="revolute">
      <origin xyz="0 0 0" rpy="${-M_PI/2} -2.756573021 0"/>
      <parent link="${name}_base_link"/>
      <child link="${name}_link1"/>
      <axis xyz="0 0 1"/>
      <limit lower="0" upper="0.994837674" effort="169" velocity="1"/>
    </joint>


    <link name="${name}_link2">
      <inertial>
        <origin rpy="0 0 0" xyz="0.18340 0.00001 0.01143"/>
        <mass value="4.72"/>
        <inertia ixx="0.04727" ixy="0.00001" ixz="0.01147" iyy="0.29026" iyz="0.00001" izz="0.25782"/>
      </inertial>
      <visual>
        <origin xyz="0 0 0" rpy="0 0 0"/>
        <geometry>
          <mesh filename="package://galbot_one_charlie_description/meshes/leg/leg_link2.obj"/>
        </geometry>

      </visual>
      <collision>
        <origin xyz="0 0 0" rpy="0 0 0"/>
        <geometry>
          <mesh filename="package://galbot_one_charlie_description/meshes/leg/leg_link2.stl"/>
        </geometry>
      </collision>
    </link>

    <joint name="${name}_joint2" type="revolute">
      <origin xyz="0.45 0 0" rpy="-${M_PI} 0 2.756573021"/>
      <parent link="${name}_link1"/>
      <child link="${name}_link2"/>
      <axis xyz="0 0 1"/>
      <limit lower="0" upper="3.05" effort="169" velocity="1"/>
    </joint>

    <link name="${name}_link3">
      <inertial>
        <origin rpy="0 0 0" xyz="0.00004 0.03287 -0.00556"/>
        <mass value="6.04"/>
        <inertia ixx="0.02981" ixy="0.00001" ixz="-0.00000" iyy="0.02294" iyz="-0.00079" izz="0.03182"/>
      </inertial>
      <visual>
        <origin xyz="0 0 0" rpy="0 0 0"/>
        <geometry>
          <mesh filename="package://galbot_one_charlie_description/meshes/leg/leg_link3.obj"/>
        </geometry>

      </visual>
      <collision>
        <origin xyz="0 0 0" rpy="0 0 0" />
        <geometry>
          <mesh filename="package://galbot_one_charlie_description/meshes/leg/leg_link3.stl"/>
        </geometry>
      </collision>
    </link>

    <joint name="${name}_joint3" type="revolute">
      <origin xyz="0.39 0 0" rpy="-${M_PI} 0 -${M_PI}"/>
      <parent link="${name}_link2"/>
      <child link="${name}_link3"/>
      <axis xyz="0 0 1"/>
      <limit lower="0" upper="2.35619449" effort="84" velocity="1"/>
    </joint>

    <link name="${name}_link4">
      <inertial>
        <origin rpy="0 0 0" xyz="0.00006 -0.00003 0.14494"/>
        <mass value="0.55"/>
        <inertia ixx="0.01267" ixy="0.00000" ixz="0.00001" iyy="0.01270" iyz="-0.00000" izz="0.00125"/>
      </inertial>
      <visual>
        <origin xyz="0 0 0" rpy="0 0 0"/>
        <geometry>
          <mesh filename="package://galbot_one_charlie_description/meshes/leg/leg_link4.obj"/>
        </geometry>

      </visual>
      <collision>
        <origin xyz="0 0 0" rpy="0 0 0" />
        <geometry>
          <mesh filename="package://galbot_one_charlie_description/meshes/leg/leg_link4.stl"/>
        </geometry>
      </collision>
    </link>

    <joint name="${name}_joint4" type="revolute">
      <origin xyz="0 0 0" rpy="${M_PI/2} 0 ${-M_PI}"/>
      <parent link="${name}_link3"/>
      <child link="${name}_link4"/>
      <axis xyz="0 0 1"/>
      <limit lower="-1.570796327" upper="1.570796327" effort="30" velocity="1"/>
    </joint>

    <link name="${name}_end_effector_mount_link">
      <inertial>
        <origin xyz="0 0 0" rpy="0 0 0" />
        <mass value="0" />
        <inertia ixx="0" ixy="0" ixz="0" iyy="0" iyz="0" izz="0" />
      </inertial>
    </link>
    <joint name="${name}_end_effector_mount_joint" type="fixed">
      <origin xyz="0 0 0" rpy="0 0 0"/>
      <parent link="${name}_link4"/>
      <child link="${name}_end_effector_mount_link"/>
      <axis xyz="0 0 0"/>
    </joint>


  </xacro:macro>
</robot>